Workbook
Name SUG_A: Lists!$J$4:INDEX(Lists!$J$4:$J$40,MAX(Lists!$I$4:$I$40))
Name SUG_D: Lists!$GB$4:INDEX(Lists!$GB$4:$GB$42,MAX(Lists!$GA$4:$GA$40)+2)
Name SUG_MAIN: Lists!$E$4:INDEX(Lists!$E$4:$E$114,MAX(Lists!$D$4:$D$114))
Name SUG_B: Lists!$GF$4:INDEX(Lists!$GF$4:$GF$42,MAX(Lists!$GE$4:$GE$40)+2)
Name SUG_C: Lists!$GJ$4:INDEX(Lists!$GJ$4:$GJ$42,MAX(Lists!$GI$4:$GI$40)+2)
Name SUG_E: Lists!$GN$4:INDEX(Lists!$GN$4:$GN$42,MAX(Lists!$GM$4:$GM$40)+2)
Name SUG_F: Lists!$GR$4:INDEX(Lists!$GR$4:$GR$42,MAX(Lists!$GQ$4:$GQ$40)+2)
Name SUG_G: Lists!$GV$4:INDEX(Lists!$GV$4:$GV$42,MAX(Lists!$GU$4:$GU$40)+2)
Name SUG_H: Lists!$GZ$4:INDEX(Lists!$GZ$4:$GZ$42,MAX(Lists!$GY$4:$GY$40)+2)
Name SUG_I: Lists!$HD$4:INDEX(Lists!$HD$4:$HD$42,MAX(Lists!$HC$4:$HC$40)+2)
Name SUG_J: Lists!$HH$4:INDEX(Lists!$HH$4:$HH$42,MAX(Lists!$HG$4:$HG$40)+2)
Name SUG_K: Lists!$HL$4:INDEX(Lists!$HL$4:$HL$42,MAX(Lists!$HK$4:$HK$40)+2)
Name SUG_L: Lists!$HP$4:INDEX(Lists!$HP$4:$HP$42,MAX(Lists!$HO$4:$HO$40)+2)
Name SUG_M: Lists!$HT$4:INDEX(Lists!$HT$4:$HT$42,MAX(Lists!$HS$4:$HS$40)+2)
Name SUG_N: Lists!$HX$4:INDEX(Lists!$HX$4:$HX$42,MAX(Lists!$HW$4:$HW$40)+2)
Name SUG_O: Lists!$IB$4:INDEX(Lists!$IB$4:$IB$42,MAX(Lists!$IA$4:$IA$40)+2)
Name SUG_P: Lists!$IF$4:INDEX(Lists!$IF$4:$IF$42,MAX(Lists!$IE$4:$IE$40)+2)
Name SUG_Q: Lists!$IJ$4:INDEX(Lists!$IJ$4:$IJ$42,MAX(Lists!$II$4:$II$40)+2)
Name SUG_R: Lists!$IN$4:INDEX(Lists!$IN$4:$IN$42,MAX(Lists!$IM$4:$IM$40)+2)
Name SUG_S: Lists!$IR$4:INDEX(Lists!$IR$4:$IR$42,MAX(Lists!$IQ$4:$IQ$40)+2)
Name SUG_T: Lists!$IV$4:INDEX(Lists!$IV$4:$IV$42,MAX(Lists!$IU$4:$IU$40)+2)
Name SUG_U: Lists!$IZ$4:INDEX(Lists!$IZ$4:$IZ$42,MAX(Lists!$IY$4:$IY$40)+2)
Name SUG_V: Lists!$JD$4:INDEX(Lists!$JD$4:$JD$42,MAX(Lists!$JC$4:$JC$40)+2)
Name SUG_W: Lists!$JH$4:INDEX(Lists!$JH$4:$JH$42,MAX(Lists!$JG$4:$JG$40)+2)
Name SUG_X: Lists!$JL$4:INDEX(Lists!$JL$4:$JL$42,MAX(Lists!$JK$4:$JK$40)+2)
Name SUG_Y: Lists!$JP$4:INDEX(Lists!$JP$4:$JP$42,MAX(Lists!$JO$4:$JO$40)+2)
Name SUG_Z: Lists!$JT$4:INDEX(Lists!$JT$4:$JT$42,MAX(Lists!$JS$4:$JS$40)+2)
Name SUG_AA: Lists!$JX$4:INDEX(Lists!$JX$4:$JX$42,MAX(Lists!$JW$4:$JW$40)+2)
Name SUG_AB: Lists!$KB$4:INDEX(Lists!$KB$4:$KB$42,MAX(Lists!$KA$4:$KA$40)+2)
Name SUG_AC: Lists!$KF$4:INDEX(Lists!$KF$4:$KF$42,MAX(Lists!$KE$4:$KE$40)+2)
Name SUG_AD: Lists!$KJ$4:INDEX(Lists!$KJ$4:$KJ$42,MAX(Lists!$KI$4:$KI$40)+2)
Name SUG_AE: Lists!$KN$4:INDEX(Lists!$KN$4:$KN$42,MAX(Lists!$KM$4:$KM$40)+2)
Name SUG_AI: Lists!$KR$4:INDEX(Lists!$KR$4:$KR$42,MAX(Lists!$KQ$4:$KQ$40)+2)
Name SUG_AF: Lists!$KV$4:INDEX(Lists!$KV$4:$KV$42,MAX(Lists!$KU$4:$KU$40)+2)
Name SUG_AG: Lists!$KZ$4:INDEX(Lists!$KZ$4:$KZ$42,MAX(Lists!$KY$4:$KY$40)+2)
Name SUG_AH: Lists!$LD$4:INDEX(Lists!$LD$4:$LD$42,MAX(Lists!$LC$4:$LC$40)+2)
Name SUGN_B: Lists!$LH$4:INDEX(Lists!$LH$4:$LH$42,MAX(Lists!$LG$4:$LG$40)+2)
Name SUGN_C: Lists!$LL$4:INDEX(Lists!$LL$4:$LL$42,MAX(Lists!$LK$4:$LK$40)+2)
Name SUGN_D: Lists!$LP$4:INDEX(Lists!$LP$4:$LP$42,MAX(Lists!$LO$4:$LO$40)+2)
Name SUGN_E: Lists!$LT$4:INDEX(Lists!$LT$4:$LT$42,MAX(Lists!$LS$4:$LS$40)+2)
Name SUGN_F: Lists!$LX$4:INDEX(Lists!$LX$4:$LX$42,MAX(Lists!$LW$4:$LW$40)+2)
Name SUGN_G: Lists!$MB$4:INDEX(Lists!$MB$4:$MB$42,MAX(Lists!$MA$4:$MA$40)+2)
Name SUGN_H: Lists!$MF$4:INDEX(Lists!$MF$4:$MF$42,MAX(Lists!$ME$4:$ME$40)+2)
Name SUGN_I: Lists!$MJ$4:INDEX(Lists!$MJ$4:$MJ$42,MAX(Lists!$MI$4:$MI$40)+2)
Name SUGN_J: Lists!$MN$4:INDEX(Lists!$MN$4:$MN$42,MAX(Lists!$MM$4:$MM$40)+2)
Name SUGN_K: Lists!$MR$4:INDEX(Lists!$MR$4:$MR$42,MAX(Lists!$MQ$4:$MQ$40)+2)
Name SUGN_L: Lists!$MV$4:INDEX(Lists!$MV$4:$MV$42,MAX(Lists!$MU$4:$MU$40)+2)
Name SUGN_M: Lists!$MZ$4:INDEX(Lists!$MZ$4:$MZ$42,MAX(Lists!$MY$4:$MY$40)+2)
Name SUGN_N: Lists!$ND$4:INDEX(Lists!$ND$4:$ND$42,MAX(Lists!$NC$4:$NC$40)+2)
Name SUGN_O: Lists!$NH$4:INDEX(Lists!$NH$4:$NH$42,MAX(Lists!$NG$4:$NG$40)+2)
Name SUGN_P: Lists!$NL$4:INDEX(Lists!$NL$4:$NL$42,MAX(Lists!$NK$4:$NK$40)+2)
Name SUGN_Q: Lists!$NP$4:INDEX(Lists!$NP$4:$NP$42,MAX(Lists!$NO$4:$NO$40)+2)
Name SUGN_R: Lists!$NT$4:INDEX(Lists!$NT$4:$NT$42,MAX(Lists!$NS$4:$NS$40)+2)
Name SUGN_S: Lists!$NX$4:INDEX(Lists!$NX$4:$NX$42,MAX(Lists!$NW$4:$NW$40)+2)
Name SUGN_T: Lists!$OB$4:INDEX(Lists!$OB$4:$OB$42,MAX(Lists!$OA$4:$OA$40)+2)
Name SUGN_U: Lists!$OF$4:INDEX(Lists!$OF$4:$OF$42,MAX(Lists!$OE$4:$OE$40)+2)
Name SUGN_V: Lists!$OJ$4:INDEX(Lists!$OJ$4:$OJ$42,MAX(Lists!$OI$4:$OI$40)+2)
Name SUGN_W: Lists!$ON$4:INDEX(Lists!$ON$4:$ON$42,MAX(Lists!$OM$4:$OM$40)+2)
Name SUGN_X: Lists!$OR$4:INDEX(Lists!$OR$4:$OR$42,MAX(Lists!$OQ$4:$OQ$40)+2)
Name SUGN_Y: Lists!$OV$4:INDEX(Lists!$OV$4:$OV$42,MAX(Lists!$OU$4:$OU$40)+2)

Sheet Final Calculation Sheet
B1: MSTC LIMITED - COMBINED BID SHEET (Auctions 21977, 21978, 21979, 21980)
AI2: =IF(COUNTIF($A$2:$AH$2,"<>")=0,"🔍 SEARCH - nothing typed yet, all 37 rows are shown. · type in any yellow box above a column, or pick from its dropdown: every column is searched, the boxes are ANDed together, (blank)/(nonblank) and * / ? work as usual","🔍 MATCHED "&SUM($BT$4:$BT$40)&" of 37 row(s) · the rows that miss are greyed out, nothing is hidden and the totals still cover all 37 · clear a box to widen the dropdowns again")
A3: Quantity | B3: Lot No. | C3: Rate | D3: Bid Sheet | E3: Unit | F3: Lot No. | G3: Buyer | H3: Mat. Value | I3: GST | J3: Mat. Value + GST | K3: TCS | L3: TDS u/s 194(O) | M3: Service Charge to MSTC | N3: TDS u/s 194(H) | O3: Net Service Charge (post TDS 194H) | P3: Service charge to MSTC | Q3: GST TDS Rate | R3: GST TDS | S3: Total Receivables in Cash | T3: Security Deposit (Expected) | U3: Security Deposit (Received) | V3: Date of Receipt | W3: Final Payment (Expected) | X3: Final Payment (Received) | Y3: Date of Receipt | Z3: LPP Expected | AA3: LPP Received | AB3: Date of Recepit of LPP | AC3: Total Received | AD3: Outstanding | AE3: Payment Status | AF3: Invoice No. | AG3: SAP Document | AH3: Doc./Invoice Date
A4: 669 | B4: SCRAP COPPER OF T/F WINDING (Oil impregnated paper insulated T/F winding) | C4: 1181 | D4: 21980 | E4: KG | F4: 1763 | G4: AL HAMD TRADE CORPORATION | H4: 790089 | I4: =ROUND(H4*18%,0) | J4: =+H4+I4 | K4: =ROUND((H4+I4)*2%,0) | L4: =H4*0.1% | M4: =H4*2.25%*118% | N4: =H4*2.25%*2% | O4: =M4-N4 | P4: =ROUND(O4+L4,0) | Q4: 0.02 | R4: =ROUND(H4*Q4,0) | S4: =ROUND(H4*117.65%-R4,0) | T4: =ROUND(H4*25%,0) | U4: 197522 | V4: 24.08.2026 | W4: =ROUND(H4*92.65%-R4,0) | X4: 716216 | Y4: 18.08.2026 | Z4: =IF(IF(OR(AB4="",AB4=0),TODAY(),DATE(VALUE(RIGHT(AB4,4)),VALUE(MID(AB4,4,2)),VALUE(LEFT(AB4,2))))<=DATE(2026,8,24),0,H4*0.0118*CEILING((IF(OR(AB4="",AB4=0),TODAY(),DATE(VALUE(RIGHT(AB4,4)),VALUE(MID(AB4,4,2)),VALUE(LEFT(AB4,2))))-DATE(2026,8,22))/7,1)) | AC4: =U4+X4+AA4 | AD4: =S4-AC4 | AE4: =IF(AD4="","",IF(AD4<=5,"SETTLED","OUTSTANDING")) | AF4: DR2640100029 | AG4: 1800003271 | AH4: 24.08.2026 | AL4: =IF($A$2="",1,IF($A$2="(blank)",--(A4=""),IF($A$2="(nonblank)",--(A4<>""),--ISNUMBER(SEARCH($A$2,A4))))) | AM4: =IF($B$2="",1,IF($B$2="(blank)",--(B4=""),IF($B$2="(nonblank)",--(B4<>""),--ISNUMBER(SEARCH($B$2,B4))))) | AN4: =IF($C$2="",1,IF($C$2="(blank)",--(C4=""),IF($C$2="(nonblank)",--(C4<>""),--ISNUMBER(SEARCH($C$2,C4))))) | AO4: =IF($D$2="",1,IF($D$2="(blank)",--(D4=""),IF($D$2="(nonblank)",--(D4<>""),--ISNUMBER(SEARCH($D$2,D4))))) | AP4: =IF($E$2="",1,IF($E$2="(blank)",--(E4=""),IF($E$2="(nonblank)",--(E4<>""),--ISNUMBER(SEARCH($E$2,E4))))) | AQ4: =IF($F$2="",1,IF($F$2="(blank)",--(F4=""),IF($F$2="(nonblank)",--(F4<>""),--ISNUMBER(SEARCH($F$2,F4))))) | AR4: =IF($G$2="",1,IF($G$2="(blank)",--(G4=""),IF($G$2="(nonblank)",--(G4<>""),--ISNUMBER(SEARCH($G$2,G4))))) | AS4: =IF($H$2="",1,IF($H$2="(blank)",--(H4=""),IF($H$2="(nonblank)",--(H4<>""),--ISNUMBER(SEARCH($H$2,H4))))) | AT4: =IF($I$2="",1,IF($I$2="(blank)",--(I4=""),IF($I$2="(nonblank)",--(I4<>""),--ISNUMBER(SEARCH($I$2,I4))))) | AU4: =IF($J$2="",1,IF($J$2="(blank)",--(J4=""),IF($J$2="(nonblank)",--(J4<>""),--ISNUMBER(SEARCH($J$2,J4))))) | AV4: =IF($K$2="",1,IF($K$2="(blank)",--(K4=""),IF($K$2="(nonblank)",--(K4<>""),--ISNUMBER(SEARCH($K$2,K4))))) | AW4: =IF($L$2="",1,IF($L$2="(blank)",--(L4=""),IF($L$2="(nonblank)",--(L4<>""),--ISNUMBER(SEARCH($L$2,L4))))) | AX4: =IF($M$2="",1,IF($M$2="(blank)",--(M4=""),IF($M$2="(nonblank)",--(M4<>""),--ISNUMBER(SEARCH($M$2,M4))))) | AY4: =IF($N$2="",1,IF($N$2="(blank)",--(N4=""),IF($N$2="(nonblank)",--(N4<>""),--ISNUMBER(SEARCH($N$2,N4))))) | AZ4: =IF($O$2="",1,IF($O$2="(blank)",--(O4=""),IF($O$2="(nonblank)",--(O4<>""),--ISNUMBER(SEARCH($O$2,O4))))) | BA4: =IF($P$2="",1,IF($P$2="(blank)",--(P4=""),IF($P$2="(nonblank)",--(P4<>""),--ISNUMBER(SEARCH($P$2,P4))))) | BB4: =IF($Q$2="",1,IF($Q$2="(blank)",--(Q4=""),IF($Q$2="(nonblank)",--(Q4<>""),--ISNUMBER(SEARCH($Q$2,Q4))))) | BC4: =IF($R$2="",1,IF($R$2="(blank)",--(R4=""),IF($R$2="(nonblank)",--(R4<>""),--ISNUMBER(SEARCH($R$2,R4))))) | BD4: =IF($S$2="",1,IF($S$2="(blank)",--(S4=""),IF($S$2="(nonblank)",--(S4<>""),--ISNUMBER(SEARCH($S$2,S4))))) | BE4: =IF($T$2="",1,IF($T$2="(blank)",--(T4=""),IF($T$2="(nonblank)",--(T4<>""),--ISNUMBER(SEARCH($T$2,T4))))) | BF4: =IF($U$2="",1,IF($U$2="(blank)",--(U4=""),IF($U$2="(nonblank)",--(U4<>""),--ISNUMBER(SEARCH($U$2,U4))))) | BG4: =IF($V$2="",1,IF($V$2="(blank)",--(V4=""),IF($V$2="(nonblank)",--(V4<>""),--ISNUMBER(SEARCH($V$2,V4))))) | BH4: =IF($W$2="",1,IF($W$2="(blank)",--(W4=""),IF($W$2="(nonblank)",--(W4<>""),--ISNUMBER(SEARCH($W$2,W4))))) | BI4: =IF($X$2="",1,IF($X$2="(blank)",--(X4=""),IF($X$2="(nonblank)",--(X4<>""),--ISNUMBER(SEARCH($X$2,X4))))) | BJ4: =IF($Y$2="",1,IF($Y$2="(blank)",--(Y4=""),IF($Y$2="(nonblank)",--(Y4<>""),--ISNUMBER(SEARCH($Y$2,Y4))))) | BK4: =IF($Z$2="",1,IF($Z$2="(blank)",--(Z4=""),IF($Z$2="(nonblank)",--(Z4<>""),--ISNUMBER(SEARCH($Z$2,Z4))))) | BL4: =IF($AA$2="",1,IF($AA$2="(blank)",--(AA4=""),IF($AA$2="(nonblank)",--(AA4<>""),--ISNUMBER(SEARCH($AA$2,AA4))))) | BM4: =IF($AB$2="",1,IF($AB$2="(blank)",--(AB4=""),IF($AB$2="(nonblank)",--(AB4<>""),--ISNUMBER(SEARCH($AB$2,AB4))))) | BN4: =IF($AC$2="",1,IF($AC$2="(blank)",--(AC4=""),IF($AC$2="(nonblank)",--(AC4<>""),--ISNUMBER(SEARCH($AC$2,AC4))))) | BO4: =IF($AD$2="",1,IF($AD$2="(blank)",--(AD4=""),IF($AD$2="(nonblank)",--(AD4<>""),--ISNUMBER(SEARCH($AD$2,AD4))))) | BP4: =IF($AE$2="",1,IF($AE$2="(blank)",--(AE4=""),IF($AE$2="(nonblank)",--(AE4<>""),--ISNUMBER(SEARCH($AE$2,AE4))))) | BQ4: =IF($AF$2="",1,IF($AF$2="(blank)",--(AF4=""),IF($AF$2="(nonblank)",--(AF4<>""),--ISNUMBER(SEARCH($AF$2,AF4))))) | BR4: =IF($AG$2="",1,IF($AG$2="(blank)",--(AG4=""),IF($AG$2="(nonblank)",--(AG4<>""),--ISNUMBER(SEARCH($AG$2,AG4))))) | BS4: =IF($AH$2="",1,IF($AH$2="(blank)",--(AH4=""),IF($AH$2="(nonblank)",--(AH4<>""),--ISNUMBER(SEARCH($AH$2,AH4))))) | BT4: =IF(COUNTIF($AL4:$BS4,0)>0,0,1)
A5: 270 | B5: Scrap of Empty oil drum | C5: 580 | D5: 21977 | E5: NO | F5: 1874 | G5: NATIONAL ENTERPRISES | H5: 156600 | I5: =ROUND(H5*18%,0) | J5: =+H5+I5 | K5: =ROUND((H5+I5)*2%,0) | L5: =H5*0.1% | M5: =H5*2.25%*118% | N5: =H5*2.25%*2% | O5: =M5-N5 | P5: =ROUND(O5+L5,0) | Q5: 0 | R5: =ROUND(H5*Q5,0) | S5: =ROUND(H5*117.65%-R5,0) | T5: =ROUND(H5*25%,0) | U5: =+T5 | V5: 13.08.2026 | W5: =ROUND(H5*92.65%-R5,0) | X5: 145090 | Y5: 24.08.2026 | Z5: =IF(IF(OR(AB5="",AB5=0),TODAY(),DATE(VALUE(RIGHT(AB5,4)),VALUE(MID(AB5,4,2)),VALUE(LEFT(AB5,2))))<=DATE(2026,8,24),0,H5*0.0118*CEILING((IF(OR(AB5="",AB5=0),TODAY(),DATE(VALUE(RIGHT(AB5,4)),VALUE(MID(AB5,4,2)),VALUE(LEFT(AB5,2))))-DATE(2026,8,22))/7,1)) | AC5: =U5+X5+AA5 | AD5: =S5-AC5 | AE5: =IF(AD5="","",IF(AD5<=5,"SETTLED","OUTSTANDING")) | AF5: DR2640100030 | AG5: 1800003302 | AH5: 27.08.2026 | AL5: =IF($A$2="",1,IF($A$2="(blank)",--(A5=""),IF($A$2="(nonblank)",--(A5<>""),--ISNUMBER(SEARCH($A$2,A5))))) | AM5: =IF($B$2="",1,IF($B$2="(blank)",--(B5=""),IF($B$2="(nonblank)",--(B5<>""),--ISNUMBER(SEARCH($B$2,B5))))) | AN5: =IF($C$2="",1,IF($C$2="(blank)",--(C5=""),IF($C$2="(nonblank)",--(C5<>""),--ISNUMBER(SEARCH($C$2,C5))))) | AO5: =IF($D$2="",1,IF($D$2="(blank)",--(D5=""),IF($D$2="(nonblank)",--(D5<>""),--ISNUMBER(SEARCH($D$2,D5))))) | AP5: =IF($E$2="",1,IF($E$2="(blank)",--(E5=""),IF($E$2="(nonblank)",--(E5<>""),--ISNUMBER(SEARCH($E$2,E5))))) | AQ5: =IF($F$2="",1,IF($F$2="(blank)",--(F5=""),IF($F$2="(nonblank)",--(F5<>""),--ISNUMBER(SEARCH($F$2,F5))))) | AR5: =IF($G$2="",1,IF($G$2="(blank)",--(G5=""),IF($G$2="(nonblank)",--(G5<>""),--ISNUMBER(SEARCH($G$2,G5))))) | AS5: =IF($H$2="",1,IF($H$2="(blank)",--(H5=""),IF($H$2="(nonblank)",--(H5<>""),--ISNUMBER(SEARCH($H$2,H5))))) | AT5: =IF($I$2="",1,IF($I$2="(blank)",--(I5=""),IF($I$2="(nonblank)",--(I5<>""),--ISNUMBER(SEARCH($I$2,I5))))) | AU5: =IF($J$2="",1,IF($J$2="(blank)",--(J5=""),IF($J$2="(nonblank)",--(J5<>""),--ISNUMBER(SEARCH($J$2,J5))))) | AV5: =IF($K$2="",1,IF($K$2="(blank)",--(K5=""),IF($K$2="(nonblank)",--(K5<>""),--ISNUMBER(SEARCH($K$2,K5))))) | AW5: =IF($L$2="",1,IF($L$2="(blank)",--(L5=""),IF($L$2="(nonblank)",--(L5<>""),--ISNUMBER(SEARCH($L$2,L5))))) | AX5: =IF($M$2="",1,IF($M$2="(blank)",--(M5=""),IF($M$2="(nonblank)",--(M5<>""),--ISNUMBER(SEARCH($M$2,M5))))) | AY5: =IF($N$2="",1,IF($N$2="(blank)",--(N5=""),IF($N$2="(nonblank)",--(N5<>""),--ISNUMBER(SEARCH($N$2,N5))))) | AZ5: =IF($O$2="",1,IF($O$2="(blank)",--(O5=""),IF($O$2="(nonblank)",--(O5<>""),--ISNUMBER(SEARCH($O$2,O5))))) | BA5: =IF($P$2="",1,IF($P$2="(blank)",--(P5=""),IF($P$2="(nonblank)",--(P5<>""),--ISNUMBER(SEARCH($P$2,P5))))) | BB5: =IF($Q$2="",1,IF($Q$2="(blank)",--(Q5=""),IF($Q$2="(nonblank)",--(Q5<>""),--ISNUMBER(SEARCH($Q$2,Q5))))) | BC5: =IF($R$2="",1,IF($R$2="(blank)",--(R5=""),IF($R$2="(nonblank)",--(R5<>""),--ISNUMBER(SEARCH($R$2,R5))))) | BD5: =IF($S$2="",1,IF($S$2="(blank)",--(S5=""),IF($S$2="(nonblank)",--(S5<>""),--ISNUMBER(SEARCH($S$2,S5))))) | BE5: =IF($T$2="",1,IF($T$2="(blank)",--(T5=""),IF($T$2="(nonblank)",--(T5<>""),--ISNUMBER(SEARCH($T$2,T5))))) | BF5: =IF($U$2="",1,IF($U$2="(blank)",--(U5=""),IF($U$2="(nonblank)",--(U5<>""),--ISNUMBER(SEARCH($U$2,U5))))) | BG5: =IF($V$2="",1,IF($V$2="(blank)",--(V5=""),IF($V$2="(nonblank)",--(V5<>""),--ISNUMBER(SEARCH($V$2,V5))))) | BH5: =IF($W$2="",1,IF($W$2="(blank)",--(W5=""),IF($W$2="(nonblank)",--(W5<>""),--ISNUMBER(SEARCH($W$2,W5))))) | BI5: =IF($X$2="",1,IF($X$2="(blank)",--(X5=""),IF($X$2="(nonblank)",--(X5<>""),--ISNUMBER(SEARCH($X$2,X5))))) | BJ5: =IF($Y$2="",1,IF($Y$2="(blank)",--(Y5=""),IF($Y$2="(nonblank)",--(Y5<>""),--ISNUMBER(SEARCH($Y$2,Y5))))) | BK5: =IF($Z$2="",1,IF($Z$2="(blank)",--(Z5=""),IF($Z$2="(nonblank)",--(Z5<>""),--ISNUMBER(SEARCH($Z$2,Z5))))) | BL5: =IF($AA$2="",1,IF($AA$2="(blank)",--(AA5=""),IF($AA$2="(nonblank)",--(AA5<>""),--ISNUMBER(SEARCH($AA$2,AA5))))) | BM5: =IF($AB$2="",1,IF($AB$2="(blank)",--(AB5=""),IF($AB$2="(nonblank)",--(AB5<>""),--ISNUMBER(SEARCH($AB$2,AB5))))) | BN5: =IF($AC$2="",1,IF($AC$2="(blank)",--(AC5=""),IF($AC$2="(nonblank)",--(AC5<>""),--ISNUMBER(SEARCH($AC$2,AC5))))) | BO5: =IF($AD$2="",1,IF($AD$2="(blank)",--(AD5=""),IF($AD$2="(nonblank)",--(AD5<>""),--ISNUMBER(SEARCH($AD$2,AD5))))) | BP5: =IF($AE$2="",1,IF($AE$2="(blank)",--(AE5=""),IF($AE$2="(nonblank)",--(AE5<>""),--ISNUMBER(SEARCH($AE$2,AE5))))) | BQ5: =IF($AF$2="",1,IF($AF$2="(blank)",--(AF5=""),IF($AF$2="(nonblank)",--(AF5<>""),--ISNUMBER(SEARCH($AF$2,AF5))))) | BR5: =IF($AG$2="",1,IF($AG$2="(blank)",--(AG5=""),IF($AG$2="(nonblank)",--(AG5<>""),--ISNUMBER(SEARCH($AG$2,AG5))))) | BS5: =IF($AH$2="",1,IF($AH$2="(blank)",--(AH5=""),IF($AH$2="(nonblank)",--(AH5<>""),--ISNUMBER(SEARCH($AH$2,AH5))))) | BT5: =IF(COUNTIF($AL5:$BS5,0)>0,0,1)
A6: 28 | B6: Scrap of Copper of faulty AC compressor | C6: 1456 | D6: 21977 | E6: KG | F6: 1875 | G6: F R KHANS ENTERPRISES | H6: 40768 | I6: =ROUND(H6*18%,0) | J6: =+H6+I6 | K6: =ROUND((H6+I6)*2%,0) | L6: =H6*0.1% | M6: =H6*2.25%*118% | N6: =H6*2.25%*2% | O6: =M6-N6 | P6: =ROUND(O6+L6,0) | Q6: 0 | R6: =ROUND(H6*Q6,0) | S6: =ROUND(H6*117.65%-R6,0) | T6: =ROUND(H6*25%,0) | U6: 10192 | V6: 11.08.2026 | W6: =ROUND(H6*92.65%-R6,0) | X6: =+W6+R6 | Y6: 20.08.2026 | Z6: =IF(IF(OR(AB6="",AB6=0),TODAY(),DATE(VALUE(RIGHT(AB6,4)),VALUE(MID(AB6,4,2)),VALUE(LEFT(AB6,2))))<=DATE(2026,8,24),0,H6*0.0118*CEILING((IF(OR(AB6="",AB6=0),TODAY(),DATE(VALUE(RIGHT(AB6,4)),VALUE(MID(AB6,4,2)),VALUE(LEFT(AB6,2))))-DATE(2026,8,22))/7,1)) | AC6: =U6+X6+AA6 | AD6: =S6-AC6 | AE6: =IF(AD6="","",IF(AD6<=5,"SETTLED","OUTSTANDING")) | AF6: DR2640100047 | AG6: 1800003346 | AH6: 27.08.2026 | AL6: =IF($A$2="",1,IF($A$2="(blank)",--(A6=""),IF($A$2="(nonblank)",--(A6<>""),--ISNUMBER(SEARCH($A$2,A6))))) | AM6: =IF($B$2="",1,IF($B$2="(blank)",--(B6=""),IF($B$2="(nonblank)",--(B6<>""),--ISNUMBER(SEARCH($B$2,B6))))) | AN6: =IF($C$2="",1,IF($C$2="(blank)",--(C6=""),IF($C$2="(nonblank)",--(C6<>""),--ISNUMBER(SEARCH($C$2,C6))))) | AO6: =IF($D$2="",1,IF($D$2="(blank)",--(D6=""),IF($D$2="(nonblank)",--(D6<>""),--ISNUMBER(SEARCH($D$2,D6))))) | AP6: =IF($E$2="",1,IF($E$2="(blank)",--(E6=""),IF($E$2="(nonblank)",--(E6<>""),--ISNUMBER(SEARCH($E$2,E6))))) | AQ6: =IF($F$2="",1,IF($F$2="(blank)",--(F6=""),IF($F$2="(nonblank)",--(F6<>""),--ISNUMBER(SEARCH($F$2,F6))))) | AR6: =IF($G$2="",1,IF($G$2="(blank)",--(G6=""),IF($G$2="(nonblank)",--(G6<>""),--ISNUMBER(SEARCH($G$2,G6))))) | AS6: =IF($H$2="",1,IF($H$2="(blank)",--(H6=""),IF($H$2="(nonblank)",--(H6<>""),--ISNUMBER(SEARCH($H$2,H6))))) | AT6: =IF($I$2="",1,IF($I$2="(blank)",--(I6=""),IF($I$2="(nonblank)",--(I6<>""),--ISNUMBER(SEARCH($I$2,I6))))) | AU6: =IF($J$2="",1,IF($J$2="(blank)",--(J6=""),IF($J$2="(nonblank)",--(J6<>""),--ISNUMBER(SEARCH($J$2,J6))))) | AV6: =IF($K$2="",1,IF($K$2="(blank)",--(K6=""),IF($K$2="(nonblank)",--(K6<>""),--ISNUMBER(SEARCH($K$2,K6))))) | AW6: =IF($L$2="",1,IF($L$2="(blank)",--(L6=""),IF($L$2="(nonblank)",--(L6<>""),--ISNUMBER(SEARCH($L$2,L6))))) | AX6: =IF($M$2="",1,IF($M$2="(blank)",--(M6=""),IF($M$2="(nonblank)",--(M6<>""),--ISNUMBER(SEARCH($M$2,M6))))) | AY6: =IF($N$2="",1,IF($N$2="(blank)",--(N6=""),IF($N$2="(nonblank)",--(N6<>""),--ISNUMBER(SEARCH($N$2,N6))))) | AZ6: =IF($O$2="",1,IF($O$2="(blank)",--(O6=""),IF($O$2="(nonblank)",--(O6<>""),--ISNUMBER(SEARCH($O$2,O6))))) | BA6: =IF($P$2="",1,IF($P$2="(blank)",--(P6=""),IF($P$2="(nonblank)",--(P6<>""),--ISNUMBER(SEARCH($P$2,P6))))) | BB6: =IF($Q$2="",1,IF($Q$2="(blank)",--(Q6=""),IF($Q$2="(nonblank)",--(Q6<>""),--ISNUMBER(SEARCH($Q$2,Q6))))) | BC6: =IF($R$2="",1,IF($R$2="(blank)",--(R6=""),IF($R$2="(nonblank)",--(R6<>""),--ISNUMBER(SEARCH($R$2,R6))))) | BD6: =IF($S$2="",1,IF($S$2="(blank)",--(S6=""),IF($S$2="(nonblank)",--(S6<>""),--ISNUMBER(SEARCH($S$2,S6))))) | BE6: =IF($T$2="",1,IF($T$2="(blank)",--(T6=""),IF($T$2="(nonblank)",--(T6<>""),--ISNUMBER(SEARCH($T$2,T6))))) | BF6: =IF($U$2="",1,IF($U$2="(blank)",--(U6=""),IF($U$2="(nonblank)",--(U6<>""),--ISNUMBER(SEARCH($U$2,U6))))) | BG6: =IF($V$2="",1,IF($V$2="(blank)",--(V6=""),IF($V$2="(nonblank)",--(V6<>""),--ISNUMBER(SEARCH($V$2,V6))))) | BH6: =IF($W$2="",1,IF($W$2="(blank)",--(W6=""),IF($W$2="(nonblank)",--(W6<>""),--ISNUMBER(SEARCH($W$2,W6))))) | BI6: =IF($X$2="",1,IF($X$2="(blank)",--(X6=""),IF($X$2="(nonblank)",--(X6<>""),--ISNUMBER(SEARCH($X$2,X6))))) | BJ6: =IF($Y$2="",1,IF($Y$2="(blank)",--(Y6=""),IF($Y$2="(nonblank)",--(Y6<>""),--ISNUMBER(SEARCH($Y$2,Y6))))) | BK6: =IF($Z$2="",1,IF($Z$2="(blank)",--(Z6=""),IF($Z$2="(nonblank)",--(Z6<>""),--ISNUMBER(SEARCH($Z$2,Z6))))) | BL6: =IF($AA$2="",1,IF($AA$2="(blank)",--(AA6=""),IF($AA$2="(nonblank)",--(AA6<>""),--ISNUMBER(SEARCH($AA$2,AA6))))) | BM6: =IF($AB$2="",1,IF($AB$2="(blank)",--(AB6=""),IF($AB$2="(nonblank)",--(AB6<>""),--ISNUMBER(SEARCH($AB$2,AB6))))) | BN6: =IF($AC$2="",1,IF($AC$2="(blank)",--(AC6=""),IF($AC$2="(nonblank)",--(AC6<>""),--ISNUMBER(SEARCH($AC$2,AC6))))) | BO6: =IF($AD$2="",1,IF($AD$2="(blank)",--(AD6=""),IF($AD$2="(nonblank)",--(AD6<>""),--ISNUMBER(SEARCH($AD$2,AD6))))) | BP6: =IF($AE$2="",1,IF($AE$2="(blank)",--(AE6=""),IF($AE$2="(nonblank)",--(AE6<>""),--ISNUMBER(SEARCH($AE$2,AE6))))) | BQ6: =IF($AF$2="",1,IF($AF$2="(blank)",--(AF6=""),IF($AF$2="(nonblank)",--(AF6<>""),--ISNUMBER(SEARCH($AF$2,AF6))))) | BR6: =IF($AG$2="",1,IF($AG$2="(blank)",--(AG6=""),IF($AG$2="(nonblank)",--(AG6<>""),--ISNUMBER(SEARCH($AG$2,AG6))))) | BS6: =IF($AH$2="",1,IF($AH$2="(blank)",--(AH6=""),IF($AH$2="(nonblank)",--(AH6<>""),--ISNUMBER(SEARCH($AH$2,AH6))))) | BT6: =IF(COUNTIF($AL6:$BS6,0)>0,0,1)
A7: 3000 | B7: Scrap of MS (extracted from equip cage and empty Sf6 gas cylinder) | C7: 66 | D7: 21977 | E7: KG | F7: 1876 | G7: F R KHANS ENTERPRISES | H7: 198000 | I7: =ROUND(H7*18%,0) | J7: =+H7+I7 | K7: =ROUND((H7+I7)*2%,0) | L7: =H7*0.1% | M7: =H7*2.25%*118% | N7: =H7*2.25%*2% | O7: =M7-N7 | P7: =ROUND(O7+L7,0) | Q7: 0 | R7: =ROUND(H7*Q7,0) | S7: =ROUND(H7*117.65%-R7,0) | T7: =ROUND(H7*25%,0) | U7: 49500 | V7: 11.08.2026 | W7: =ROUND(H7*92.65%-R7,0) | X7: =+W7+R7-1 | Y7: 20.08.2026 | Z7: =IF(IF(OR(AB7="",AB7=0),TODAY(),DATE(VALUE(RIGHT(AB7,4)),VALUE(MID(AB7,4,2)),VALUE(LEFT(AB7,2))))<=DATE(2026,8,24),0,H7*0.0118*CEILING((IF(OR(AB7="",AB7=0),TODAY(),DATE(VALUE(RIGHT(AB7,4)),VALUE(MID(AB7,4,2)),VALUE(LEFT(AB7,2))))-DATE(2026,8,22))/7,1)) | AC7: =U7+X7+AA7 | AD7: =S7-AC7 | AE7: =IF(AD7="","",IF(AD7<=5,"SETTLED","OUTSTANDING")) | AF7: DR2640100048 | AG7: 1800003347 | AH7: 27.08.2026 | AL7: =IF($A$2="",1,IF($A$2="(blank)",--(A7=""),IF($A$2="(nonblank)",--(A7<>""),--ISNUMBER(SEARCH($A$2,A7))))) | AM7: =IF($B$2="",1,IF($B$2="(blank)",--(B7=""),IF($B$2="(nonblank)",--(B7<>""),--ISNUMBER(SEARCH($B$2,B7))))) | AN7: =IF($C$2="",1,IF($C$2="(blank)",--(C7=""),IF($C$2="(nonblank)",--(C7<>""),--ISNUMBER(SEARCH($C$2,C7))))) | AO7: =IF($D$2="",1,IF($D$2="(blank)",--(D7=""),IF($D$2="(nonblank)",--(D7<>""),--ISNUMBER(SEARCH($D$2,D7))))) | AP7: =IF($E$2="",1,IF($E$2="(blank)",--(E7=""),IF($E$2="(nonblank)",--(E7<>""),--ISNUMBER(SEARCH($E$2,E7))))) | AQ7: =IF($F$2="",1,IF($F$2="(blank)",--(F7=""),IF($F$2="(nonblank)",--(F7<>""),--ISNUMBER(SEARCH($F$2,F7))))) | AR7: =IF($G$2="",1,IF($G$2="(blank)",--(G7=""),IF($G$2="(nonblank)",--(G7<>""),--ISNUMBER(SEARCH($G$2,G7))))) | AS7: =IF($H$2="",1,IF($H$2="(blank)",--(H7=""),IF($H$2="(nonblank)",--(H7<>""),--ISNUMBER(SEARCH($H$2,H7))))) | AT7: =IF($I$2="",1,IF($I$2="(blank)",--(I7=""),IF($I$2="(nonblank)",--(I7<>""),--ISNUMBER(SEARCH($I$2,I7))))) | AU7: =IF($J$2="",1,IF($J$2="(blank)",--(J7=""),IF($J$2="(nonblank)",--(J7<>""),--ISNUMBER(SEARCH($J$2,J7))))) | AV7: =IF($K$2="",1,IF($K$2="(blank)",--(K7=""),IF($K$2="(nonblank)",--(K7<>""),--ISNUMBER(SEARCH($K$2,K7))))) | AW7: =IF($L$2="",1,IF($L$2="(blank)",--(L7=""),IF($L$2="(nonblank)",--(L7<>""),--ISNUMBER(SEARCH($L$2,L7))))) | AX7: =IF($M$2="",1,IF($M$2="(blank)",--(M7=""),IF($M$2="(nonblank)",--(M7<>""),--ISNUMBER(SEARCH($M$2,M7))))) | AY7: =IF($N$2="",1,IF($N$2="(blank)",--(N7=""),IF($N$2="(nonblank)",--(N7<>""),--ISNUMBER(SEARCH($N$2,N7))))) | AZ7: =IF($O$2="",1,IF($O$2="(blank)",--(O7=""),IF($O$2="(nonblank)",--(O7<>""),--ISNUMBER(SEARCH($O$2,O7))))) | BA7: =IF($P$2="",1,IF($P$2="(blank)",--(P7=""),IF($P$2="(nonblank)",--(P7<>""),--ISNUMBER(SEARCH($P$2,P7))))) | BB7: =IF($Q$2="",1,IF($Q$2="(blank)",--(Q7=""),IF($Q$2="(nonblank)",--(Q7<>""),--ISNUMBER(SEARCH($Q$2,Q7))))) | BC7: =IF($R$2="",1,IF($R$2="(blank)",--(R7=""),IF($R$2="(nonblank)",--(R7<>""),--ISNUMBER(SEARCH($R$2,R7))))) | BD7: =IF($S$2="",1,IF($S$2="(blank)",--(S7=""),IF($S$2="(nonblank)",--(S7<>""),--ISNUMBER(SEARCH($S$2,S7))))) | BE7: =IF($T$2="",1,IF($T$2="(blank)",--(T7=""),IF($T$2="(nonblank)",--(T7<>""),--ISNUMBER(SEARCH($T$2,T7))))) | BF7: =IF($U$2="",1,IF($U$2="(blank)",--(U7=""),IF($U$2="(nonblank)",--(U7<>""),--ISNUMBER(SEARCH($U$2,U7))))) | BG7: =IF($V$2="",1,IF($V$2="(blank)",--(V7=""),IF($V$2="(nonblank)",--(V7<>""),--ISNUMBER(SEARCH($V$2,V7))))) | BH7: =IF($W$2="",1,IF($W$2="(blank)",--(W7=""),IF($W$2="(nonblank)",--(W7<>""),--ISNUMBER(SEARCH($W$2,W7))))) | BI7: =IF($X$2="",1,IF($X$2="(blank)",--(X7=""),IF($X$2="(nonblank)",--(X7<>""),--ISNUMBER(SEARCH($X$2,X7))))) | BJ7: =IF($Y$2="",1,IF($Y$2="(blank)",--(Y7=""),IF($Y$2="(nonblank)",--(Y7<>""),--ISNUMBER(SEARCH($Y$2,Y7))))) | BK7: =IF($Z$2="",1,IF($Z$2="(blank)",--(Z7=""),IF($Z$2="(nonblank)",--(Z7<>""),--ISNUMBER(SEARCH($Z$2,Z7))))) | BL7: =IF($AA$2="",1,IF($AA$2="(blank)",--(AA7=""),IF($AA$2="(nonblank)",--(AA7<>""),--ISNUMBER(SEARCH($AA$2,AA7))))) | BM7: =IF($AB$2="",1,IF($AB$2="(blank)",--(AB7=""),IF($AB$2="(nonblank)",--(AB7<>""),--ISNUMBER(SEARCH($AB$2,AB7))))) | BN7: =IF($AC$2="",1,IF($AC$2="(blank)",--(AC7=""),IF($AC$2="(nonblank)",--(AC7<>""),--ISNUMBER(SEARCH($AC$2,AC7))))) | BO7: =IF($AD$2="",1,IF($AD$2="(blank)",--(AD7=""),IF($AD$2="(nonblank)",--(AD7<>""),--ISNUMBER(SEARCH($AD$2,AD7))))) | BP7: =IF($AE$2="",1,IF($AE$2="(blank)",--(AE7=""),IF($AE$2="(nonblank)",--(AE7<>""),--ISNUMBER(SEARCH($AE$2,AE7))))) | BQ7: =IF($AF$2="",1,IF($AF$2="(blank)",--(AF7=""),IF($AF$2="(nonblank)",--(AF7<>""),--ISNUMBER(SEARCH($AF$2,AF7))))) | BR7: =IF($AG$2="",1,IF($AG$2="(blank)",--(AG7=""),IF($AG$2="(nonblank)",--(AG7<>""),--ISNUMBER(SEARCH($AG$2,AG7))))) | BS7: =IF($AH$2="",1,IF($AH$2="(blank)",--(AH7=""),IF($AH$2="(nonblank)",--(AH7<>""),--ISNUMBER(SEARCH($AH$2,AH7))))) | BT7: =IF(COUNTIF($AL7:$BS7,0)>0,0,1)
A8: 7253 | B8: SCRAP ACSR CONDUCTORS (Conductor Pieces) | C8: 227 | D8: 21980 | E8: KG | F8: 1923 | G8: OMKAR STEELS | H8: 1646431 | I8: =ROUND(H8*18%,0) | J8: =+H8+I8 | K8: =ROUND((H8+I8)*2%,0) | L8: =H8*0.1% | M8: =H8*2.25%*118% | N8: =H8*2.25%*2% | O8: =M8-N8 | P8: =ROUND(O8+L8,0) | Q8: 0.02 | R8: =ROUND(H8*Q8,0) | S8: =ROUND(H8*117.65%-R8,0) | T8: =ROUND(H8*25%,0) | U8: =+T8 | V8: 14.08.2026 | W8: =ROUND(H8*92.65%-R8,0) | X8: 1492490 | Y8: 24.08.2026 | Z8: =IF(IF(OR(AB8="",AB8=0),TODAY(),DATE(VALUE(RIGHT(AB8,4)),VALUE(MID(AB8,4,2)),VALUE(LEFT(AB8,2))))<=DATE(2026,8,24),0,H8*0.0118*CEILING((IF(OR(AB8="",AB8=0),TODAY(),DATE(VALUE(RIGHT(AB8,4)),VALUE(MID(AB8,4,2)),VALUE(LEFT(AB8,2))))-DATE(2026,8,22))/7,1)) | AC8: =U8+X8+AA8 | AD8: =S8-AC8 | AE8: =IF(AD8="","",IF(AD8<=5,"SETTLED","OUTSTANDING")) | AF8: DR2640100045 | AG8: 1800003315 | AH8: 27.08.2026 | AL8: =IF($A$2="",1,IF($A$2="(blank)",--(A8=""),IF($A$2="(nonblank)",--(A8<>""),--ISNUMBER(SEARCH($A$2,A8))))) | AM8: =IF($B$2="",1,IF($B$2="(blank)",--(B8=""),IF($B$2="(nonblank)",--(B8<>""),--ISNUMBER(SEARCH($B$2,B8))))) | AN8: =IF($C$2="",1,IF($C$2="(blank)",--(C8=""),IF($C$2="(nonblank)",--(C8<>""),--ISNUMBER(SEARCH($C$2,C8))))) | AO8: =IF($D$2="",1,IF($D$2="(blank)",--(D8=""),IF($D$2="(nonblank)",--(D8<>""),--ISNUMBER(SEARCH($D$2,D8))))) | AP8: =IF($E$2="",1,IF($E$2="(blank)",--(E8=""),IF($E$2="(nonblank)",--(E8<>""),--ISNUMBER(SEARCH($E$2,E8))))) | AQ8: =IF($F$2="",1,IF($F$2="(blank)",--(F8=""),IF($F$2="(nonblank)",--(F8<>""),--ISNUMBER(SEARCH($F$2,F8))))) | AR8: =IF($G$2="",1,IF($G$2="(blank)",--(G8=""),IF($G$2="(nonblank)",--(G8<>""),--ISNUMBER(SEARCH($G$2,G8))))) | AS8: =IF($H$2="",1,IF($H$2="(blank)",--(H8=""),IF($H$2="(nonblank)",--(H8<>""),--ISNUMBER(SEARCH($H$2,H8))))) | AT8: =IF($I$2="",1,IF($I$2="(blank)",--(I8=""),IF($I$2="(nonblank)",--(I8<>""),--ISNUMBER(SEARCH($I$2,I8))))) | AU8: =IF($J$2="",1,IF($J$2="(blank)",--(J8=""),IF($J$2="(nonblank)",--(J8<>""),--ISNUMBER(SEARCH($J$2,J8))))) | AV8: =IF($K$2="",1,IF($K$2="(blank)",--(K8=""),IF($K$2="(nonblank)",--(K8<>""),--ISNUMBER(SEARCH($K$2,K8))))) | AW8: =IF($L$2="",1,IF($L$2="(blank)",--(L8=""),IF($L$2="(nonblank)",--(L8<>""),--ISNUMBER(SEARCH($L$2,L8))))) | AX8: =IF($M$2="",1,IF($M$2="(blank)",--(M8=""),IF($M$2="(nonblank)",--(M8<>""),--ISNUMBER(SEARCH($M$2,M8))))) | AY8: =IF($N$2="",1,IF($N$2="(blank)",--(N8=""),IF($N$2="(nonblank)",--(N8<>""),--ISNUMBER(SEARCH($N$2,N8))))) | AZ8: =IF($O$2="",1,IF($O$2="(blank)",--(O8=""),IF($O$2="(nonblank)",--(O8<>""),--ISNUMBER(SEARCH($O$2,O8))))) | BA8: =IF($P$2="",1,IF($P$2="(blank)",--(P8=""),IF($P$2="(nonblank)",--(P8<>""),--ISNUMBER(SEARCH($P$2,P8))))) | BB8: =IF($Q$2="",1,IF($Q$2="(blank)",--(Q8=""),IF($Q$2="(nonblank)",--(Q8<>""),--ISNUMBER(SEARCH($Q$2,Q8))))) | BC8: =IF($R$2="",1,IF($R$2="(blank)",--(R8=""),IF($R$2="(nonblank)",--(R8<>""),--ISNUMBER(SEARCH($R$2,R8))))) | BD8: =IF($S$2="",1,IF($S$2="(blank)",--(S8=""),IF($S$2="(nonblank)",--(S8<>""),--ISNUMBER(SEARCH($S$2,S8))))) | BE8: =IF($T$2="",1,IF($T$2="(blank)",--(T8=""),IF($T$2="(nonblank)",--(T8<>""),--ISNUMBER(SEARCH($T$2,T8))))) | BF8: =IF($U$2="",1,IF($U$2="(blank)",--(U8=""),IF($U$2="(nonblank)",--(U8<>""),--ISNUMBER(SEARCH($U$2,U8))))) | BG8: =IF($V$2="",1,IF($V$2="(blank)",--(V8=""),IF($V$2="(nonblank)",--(V8<>""),--ISNUMBER(SEARCH($V$2,V8))))) | BH8: =IF($W$2="",1,IF($W$2="(blank)",--(W8=""),IF($W$2="(nonblank)",--(W8<>""),--ISNUMBER(SEARCH($W$2,W8))))) | BI8: =IF($X$2="",1,IF($X$2="(blank)",--(X8=""),IF($X$2="(nonblank)",--(X8<>""),--ISNUMBER(SEARCH($X$2,X8))))) | BJ8: =IF($Y$2="",1,IF($Y$2="(blank)",--(Y8=""),IF($Y$2="(nonblank)",--(Y8<>""),--ISNUMBER(SEARCH($Y$2,Y8))))) | BK8: =IF($Z$2="",1,IF($Z$2="(blank)",--(Z8=""),IF($Z$2="(nonblank)",--(Z8<>""),--ISNUMBER(SEARCH($Z$2,Z8))))) | BL8: =IF($AA$2="",1,IF($AA$2="(blank)",--(AA8=""),IF($AA$2="(nonblank)",--(AA8<>""),--ISNUMBER(SEARCH($AA$2,AA8))))) | BM8: =IF($AB$2="",1,IF($AB$2="(blank)",--(AB8=""),IF($AB$2="(nonblank)",--(AB8<>""),--ISNUMBER(SEARCH($AB$2,AB8))))) | BN8: =IF($AC$2="",1,IF($AC$2="(blank)",--(AC8=""),IF($AC$2="(nonblank)",--(AC8<>""),--ISNUMBER(SEARCH($AC$2,AC8))))) | BO8: =IF($AD$2="",1,IF($AD$2="(blank)",--(AD8=""),IF($AD$2="(nonblank)",--(AD8<>""),--ISNUMBER(SEARCH($AD$2,AD8))))) | BP8: =IF($AE$2="",1,IF($AE$2="(blank)",--(AE8=""),IF($AE$2="(nonblank)",--(AE8<>""),--ISNUMBER(SEARCH($AE$2,AE8))))) | BQ8: =IF($AF$2="",1,IF($AF$2="(blank)",--(AF8=""),IF($AF$2="(nonblank)",--(AF8<>""),--ISNUMBER(SEARCH($AF$2,AF8))))) | BR8: =IF($AG$2="",1,IF($AG$2="(blank)",--(AG8=""),IF($AG$2="(nonblank)",--(AG8<>""),--ISNUMBER(SEARCH($AG$2,AG8))))) | BS8: =IF($AH$2="",1,IF($AH$2="(blank)",--(AH8=""),IF($AH$2="(nonblank)",--(AH8<>""),--ISNUMBER(SEARCH($AH$2,AH8))))) | BT8: =IF(COUNTIF($AL8:$BS8,0)>0,0,1)
A9: 1 | B9: Scrap Power Transformer | C9: 2787314 | D9: 21977 | E9: NO | F9: 1976 | G9: SHAR JAHAN TRADERS | H9: 2787314 | I9: =ROUND(H9*18%,0) | J9: =+H9+I9 | K9: =ROUND((H9+I9)*2%,0) | L9: =H9*0.1% | M9: =H9*2.25%*118% | N9: =H9*2.25%*2% | O9: =M9-N9 | P9: =ROUND(O9+L9,0) | Q9: 0 | R9: =ROUND(H9*Q9,0) | S9: =ROUND(H9*117.65%-R9,0) | T9: =ROUND(H9*25%,0) | U9: =+T9 | V9: 13.08.2026 | W9: =ROUND(H9*92.65%-R9,0) | X9: 2582447.1 | Y9: 13.08.2026 | Z9: =IF(IF(OR(AB9="",AB9=0),TODAY(),DATE(VALUE(RIGHT(AB9,4)),VALUE(MID(AB9,4,2)),VALUE(LEFT(AB9,2))))<=DATE(2026,8,24),0,H9*0.0118*CEILING((IF(OR(AB9="",AB9=0),TODAY(),DATE(VALUE(RIGHT(AB9,4)),VALUE(MID(AB9,4,2)),VALUE(LEFT(AB9,2))))-DATE(2026,8,22))/7,1)) | AC9: =U9+X9+AA9 | AD9: =S9-AC9 | AE9: =IF(AD9="","",IF(AD9<=5,"SETTLED","OUTSTANDING")) | AF9: DR2640100023 | AG9: 1800003194 | AH9: 17.08.2026 | AL9: =IF($A$2="",1,IF($A$2="(blank)",--(A9=""),IF($A$2="(nonblank)",--(A9<>""),--ISNUMBER(SEARCH($A$2,A9))))) | AM9: =IF($B$2="",1,IF($B$2="(blank)",--(B9=""),IF($B$2="(nonblank)",--(B9<>""),--ISNUMBER(SEARCH($B$2,B9))))) | AN9: =IF($C$2="",1,IF($C$2="(blank)",--(C9=""),IF($C$2="(nonblank)",--(C9<>""),--ISNUMBER(SEARCH($C$2,C9))))) | AO9: =IF($D$2="",1,IF($D$2="(blank)",--(D9=""),IF($D$2="(nonblank)",--(D9<>""),--ISNUMBER(SEARCH($D$2,D9))))) | AP9: =IF($E$2="",1,IF($E$2="(blank)",--(E9=""),IF($E$2="(nonblank)",--(E9<>""),--ISNUMBER(SEARCH($E$2,E9))))) | AQ9: =IF($F$2="",1,IF($F$2="(blank)",--(F9=""),IF($F$2="(nonblank)",--(F9<>""),--ISNUMBER(SEARCH($F$2,F9))))) | AR9: =IF($G$2="",1,IF($G$2="(blank)",--(G9=""),IF($G$2="(nonblank)",--(G9<>""),--ISNUMBER(SEARCH($G$2,G9))))) | AS9: =IF($H$2="",1,IF($H$2="(blank)",--(H9=""),IF($H$2="(nonblank)",--(H9<>""),--ISNUMBER(SEARCH($H$2,H9))))) | AT9: =IF($I$2="",1,IF($I$2="(blank)",--(I9=""),IF($I$2="(nonblank)",--(I9<>""),--ISNUMBER(SEARCH($I$2,I9))))) | AU9: =IF($J$2="",1,IF($J$2="(blank)",--(J9=""),IF($J$2="(nonblank)",--(J9<>""),--ISNUMBER(SEARCH($J$2,J9))))) | AV9: =IF($K$2="",1,IF($K$2="(blank)",--(K9=""),IF($K$2="(nonblank)",--(K9<>""),--ISNUMBER(SEARCH($K$2,K9))))) | AW9: =IF($L$2="",1,IF($L$2="(blank)",--(L9=""),IF($L$2="(nonblank)",--(L9<>""),--ISNUMBER(SEARCH($L$2,L9))))) | AX9: =IF($M$2="",1,IF($M$2="(blank)",--(M9=""),IF($M$2="(nonblank)",--(M9<>""),--ISNUMBER(SEARCH($M$2,M9))))) | AY9: =IF($N$2="",1,IF($N$2="(blank)",--(N9=""),IF($N$2="(nonblank)",--(N9<>""),--ISNUMBER(SEARCH($N$2,N9))))) | AZ9: =IF($O$2="",1,IF($O$2="(blank)",--(O9=""),IF($O$2="(nonblank)",--(O9<>""),--ISNUMBER(SEARCH($O$2,O9))))) | BA9: =IF($P$2="",1,IF($P$2="(blank)",--(P9=""),IF($P$2="(nonblank)",--(P9<>""),--ISNUMBER(SEARCH($P$2,P9))))) | BB9: =IF($Q$2="",1,IF($Q$2="(blank)",--(Q9=""),IF($Q$2="(nonblank)",--(Q9<>""),--ISNUMBER(SEARCH($Q$2,Q9))))) | BC9: =IF($R$2="",1,IF($R$2="(blank)",--(R9=""),IF($R$2="(nonblank)",--(R9<>""),--ISNUMBER(SEARCH($R$2,R9))))) | BD9: =IF($S$2="",1,IF($S$2="(blank)",--(S9=""),IF($S$2="(nonblank)",--(S9<>""),--ISNUMBER(SEARCH($S$2,S9))))) | BE9: =IF($T$2="",1,IF($T$2="(blank)",--(T9=""),IF($T$2="(nonblank)",--(T9<>""),--ISNUMBER(SEARCH($T$2,T9))))) | BF9: =IF($U$2="",1,IF($U$2="(blank)",--(U9=""),IF($U$2="(nonblank)",--(U9<>""),--ISNUMBER(SEARCH($U$2,U9))))) | BG9: =IF($V$2="",1,IF($V$2="(blank)",--(V9=""),IF($V$2="(nonblank)",--(V9<>""),--ISNUMBER(SEARCH($V$2,V9))))) | BH9: =IF($W$2="",1,IF($W$2="(blank)",--(W9=""),IF($W$2="(nonblank)",--(W9<>""),--ISNUMBER(SEARCH($W$2,W9))))) | BI9: =IF($X$2="",1,IF($X$2="(blank)",--(X9=""),IF($X$2="(nonblank)",--(X9<>""),--ISNUMBER(SEARCH($X$2,X9))))) | BJ9: =IF($Y$2="",1,IF($Y$2="(blank)",--(Y9=""),IF($Y$2="(nonblank)",--(Y9<>""),--ISNUMBER(SEARCH($Y$2,Y9))))) | BK9: =IF($Z$2="",1,IF($Z$2="(blank)",--(Z9=""),IF($Z$2="(nonblank)",--(Z9<>""),--ISNUMBER(SEARCH($Z$2,Z9))))) | BL9: =IF($AA$2="",1,IF($AA$2="(blank)",--(AA9=""),IF($AA$2="(nonblank)",--(AA9<>""),--ISNUMBER(SEARCH($AA$2,AA9))))) | BM9: =IF($AB$2="",1,IF($AB$2="(blank)",--(AB9=""),IF($AB$2="(nonblank)",--(AB9<>""),--ISNUMBER(SEARCH($AB$2,AB9))))) | BN9: =IF($AC$2="",1,IF($AC$2="(blank)",--(AC9=""),IF($AC$2="(nonblank)",--(AC9<>""),--ISNUMBER(SEARCH($AC$2,AC9))))) | BO9: =IF($AD$2="",1,IF($AD$2="(blank)",--(AD9=""),IF($AD$2="(nonblank)",--(AD9<>""),--ISNUMBER(SEARCH($AD$2,AD9))))) | BP9: =IF($AE$2="",1,IF($AE$2="(blank)",--(AE9=""),IF($AE$2="(nonblank)",--(AE9<>""),--ISNUMBER(SEARCH($AE$2,AE9))))) | BQ9: =IF($AF$2="",1,IF($AF$2="(blank)",--(AF9=""),IF($AF$2="(nonblank)",--(AF9<>""),--ISNUMBER(SEARCH($AF$2,AF9))))) | BR9: =IF($AG$2="",1,IF($AG$2="(blank)",--(AG9=""),IF($AG$2="(nonblank)",--(AG9<>""),--ISNUMBER(SEARCH($AG$2,AG9))))) | BS9: =IF($AH$2="",1,IF($AH$2="(blank)",--(AH9=""),IF($AH$2="(nonblank)",--(AH9<>""),--ISNUMBER(SEARCH($AH$2,AH9))))) | BT9: =IF(COUNTIF($AL9:$BS9,0)>0,0,1)
A10: 4 | B10: Scrap of 132 KV CT | C10: 51511 | D10: 21977 | E10: NO | F10: 2002 | G10: NATIONAL ENTERPRISES | H10: 206044 | I10: =ROUND(H10*18%,0) | J10: =+H10+I10 | K10: =ROUND((H10+I10)*2%,0) | L10: =H10*0.1% | M10: =H10*2.25%*118% | N10: =H10*2.25%*2% | O10: =M10-N10 | P10: =ROUND(O10+L10,0) | Q10: 0 | R10: =ROUND(H10*Q10,0) | S10: =ROUND(H10*117.65%-R10,0) | T10: =ROUND(H10*25%,0) | U10: =+T10 | V10: 13.08.2026 | W10: =ROUND(H10*92.65%-R10,0) | X10: 190900 | Y10: 24.08.2026 | Z10: =IF(IF(OR(AB10="",AB10=0),TODAY(),DATE(VALUE(RIGHT(AB10,4)),VALUE(MID(AB10,4,2)),VALUE(LEFT(AB10,2))))<=DATE(2026,8,24),0,H10*0.0118*CEILING((IF(OR(AB10="",AB10=0),TODAY(),DATE(VALUE(RIGHT(AB10,4)),VALUE(MID(AB10,4,2)),VALUE(LEFT(AB10,2))))-DATE(2026,8,22))/7,1)) | AC10: =U10+X10+AA10 | AD10: =S10-AC10 | AE10: =IF(AD10="","",IF(AD10<=5,"SETTLED","OUTSTANDING")) | AF10: DR2640100031 | AG10: 1800003303 | AH10: 27.08.2026 | AL10: =IF($A$2="",1,IF($A$2="(blank)",--(A10=""),IF($A$2="(nonblank)",--(A10<>""),--ISNUMBER(SEARCH($A$2,A10))))) | AM10: =IF($B$2="",1,IF($B$2="(blank)",--(B10=""),IF($B$2="(nonblank)",--(B10<>""),--ISNUMBER(SEARCH($B$2,B10))))) | AN10: =IF($C$2="",1,IF($C$2="(blank)",--(C10=""),IF($C$2="(nonblank)",--(C10<>""),--ISNUMBER(SEARCH($C$2,C10))))) | AO10: =IF($D$2="",1,IF($D$2="(blank)",--(D10=""),IF($D$2="(nonblank)",--(D10<>""),--ISNUMBER(SEARCH($D$2,D10))))) | AP10: =IF($E$2="",1,IF($E$2="(blank)",--(E10=""),IF($E$2="(nonblank)",--(E10<>""),--ISNUMBER(SEARCH($E$2,E10))))) | AQ10: =IF($F$2="",1,IF($F$2="(blank)",--(F10=""),IF($F$2="(nonblank)",--(F10<>""),--ISNUMBER(SEARCH($F$2,F10))))) | AR10: =IF($G$2="",1,IF($G$2="(blank)",--(G10=""),IF($G$2="(nonblank)",--(G10<>""),--ISNUMBER(SEARCH($G$2,G10))))) | AS10: =IF($H$2="",1,IF($H$2="(blank)",--(H10=""),IF($H$2="(nonblank)",--(H10<>""),--ISNUMBER(SEARCH($H$2,H10))))) | AT10: =IF($I$2="",1,IF($I$2="(blank)",--(I10=""),IF($I$2="(nonblank)",--(I10<>""),--ISNUMBER(SEARCH($I$2,I10))))) | AU10: =IF($J$2="",1,IF($J$2="(blank)",--(J10=""),IF($J$2="(nonblank)",--(J10<>""),--ISNUMBER(SEARCH($J$2,J10))))) | AV10: =IF($K$2="",1,IF($K$2="(blank)",--(K10=""),IF($K$2="(nonblank)",--(K10<>""),--ISNUMBER(SEARCH($K$2,K10))))) | AW10: =IF($L$2="",1,IF($L$2="(blank)",--(L10=""),IF($L$2="(nonblank)",--(L10<>""),--ISNUMBER(SEARCH($L$2,L10))))) | AX10: =IF($M$2="",1,IF($M$2="(blank)",--(M10=""),IF($M$2="(nonblank)",--(M10<>""),--ISNUMBER(SEARCH($M$2,M10))))) | AY10: =IF($N$2="",1,IF($N$2="(blank)",--(N10=""),IF($N$2="(nonblank)",--(N10<>""),--ISNUMBER(SEARCH($N$2,N10))))) | AZ10: =IF($O$2="",1,IF($O$2="(blank)",--(O10=""),IF($O$2="(nonblank)",--(O10<>""),--ISNUMBER(SEARCH($O$2,O10))))) | BA10: =IF($P$2="",1,IF($P$2="(blank)",--(P10=""),IF($P$2="(nonblank)",--(P10<>""),--ISNUMBER(SEARCH($P$2,P10))))) | BB10: =IF($Q$2="",1,IF($Q$2="(blank)",--(Q10=""),IF($Q$2="(nonblank)",--(Q10<>""),--ISNUMBER(SEARCH($Q$2,Q10))))) | BC10: =IF($R$2="",1,IF($R$2="(blank)",--(R10=""),IF($R$2="(nonblank)",--(R10<>""),--ISNUMBER(SEARCH($R$2,R10))))) | BD10: =IF($S$2="",1,IF($S$2="(blank)",--(S10=""),IF($S$2="(nonblank)",--(S10<>""),--ISNUMBER(SEARCH($S$2,S10))))) | BE10: =IF($T$2="",1,IF($T$2="(blank)",--(T10=""),IF($T$2="(nonblank)",--(T10<>""),--ISNUMBER(SEARCH($T$2,T10))))) | BF10: =IF($U$2="",1,IF($U$2="(blank)",--(U10=""),IF($U$2="(nonblank)",--(U10<>""),--ISNUMBER(SEARCH($U$2,U10))))) | BG10: =IF($V$2="",1,IF($V$2="(blank)",--(V10=""),IF($V$2="(nonblank)",--(V10<>""),--ISNUMBER(SEARCH($V$2,V10))))) | BH10: =IF($W$2="",1,IF($W$2="(blank)",--(W10=""),IF($W$2="(nonblank)",--(W10<>""),--ISNUMBER(SEARCH($W$2,W10))))) | BI10: =IF($X$2="",1,IF($X$2="(blank)",--(X10=""),IF($X$2="(nonblank)",--(X10<>""),--ISNUMBER(SEARCH($X$2,X10))))) | BJ10: =IF($Y$2="",1,IF($Y$2="(blank)",--(Y10=""),IF($Y$2="(nonblank)",--(Y10<>""),--ISNUMBER(SEARCH($Y$2,Y10))))) | BK10: =IF($Z$2="",1,IF($Z$2="(blank)",--(Z10=""),IF($Z$2="(nonblank)",--(Z10<>""),--ISNUMBER(SEARCH($Z$2,Z10))))) | BL10: =IF($AA$2="",1,IF($AA$2="(blank)",--(AA10=""),IF($AA$2="(nonblank)",--(AA10<>""),--ISNUMBER(SEARCH($AA$2,AA10))))) | BM10: =IF($AB$2="",1,IF($AB$2="(blank)",--(AB10=""),IF($AB$2="(nonblank)",--(AB10<>""),--ISNUMBER(SEARCH($AB$2,AB10))))) | BN10: =IF($AC$2="",1,IF($AC$2="(blank)",--(AC10=""),IF($AC$2="(nonblank)",--(AC10<>""),--ISNUMBER(SEARCH($AC$2,AC10))))) | BO10: =IF($AD$2="",1,IF($AD$2="(blank)",--(AD10=""),IF($AD$2="(nonblank)",--(AD10<>""),--ISNUMBER(SEARCH($AD$2,AD10))))) | BP10: =IF($AE$2="",1,IF($AE$2="(blank)",--(AE10=""),IF($AE$2="(nonblank)",--(AE10<>""),--ISNUMBER(SEARCH($AE$2,AE10))))) | BQ10: =IF($AF$2="",1,IF($AF$2="(blank)",--(AF10=""),IF($AF$2="(nonblank)",--(AF10<>""),--ISNUMBER(SEARCH($AF$2,AF10))))) | BR10: =IF($AG$2="",1,IF($AG$2="(blank)",--(AG10=""),IF($AG$2="(nonblank)",--(AG10<>""),--ISNUMBER(SEARCH($AG$2,AG10))))) | BS10: =IF($AH$2="",1,IF($AH$2="(blank)",--(AH10=""),IF($AH$2="(nonblank)",--(AH10<>""),--ISNUMBER(SEARCH($AH$2,AH10))))) | BT10: =IF(COUNTIF($AL10:$BS10,0)>0,0,1)
A11: 1 | B11: Scrap of 145 KV CB | C11: 65007 | D11: 21977 | E11: NO | F11: 2003 | G11: NATIONAL ENTERPRISES | H11: 65007 | I11: =ROUND(H11*18%,0) | J11: =+H11+I11 | K11: =ROUND((H11+I11)*2%,0) | L11: =H11*0.1% | M11: =H11*2.25%*118% | N11: =H11*2.25%*2% | O11: =M11-N11 | P11: =ROUND(O11+L11,0) | Q11: 0 | R11: =ROUND(H11*Q11,0) | S11: =ROUND(H11*117.65%-R11,0) | T11: =ROUND(H11*25%,0) | U11: =+T11 | V11: 13.08.2026 | W11: =ROUND(H11*92.65%-R11,0) | X11: 60229 | Y11: 24.08.2026 | Z11: =IF(IF(OR(AB11="",AB11=0),TODAY(),DATE(VALUE(RIGHT(AB11,4)),VALUE(MID(AB11,4,2)),VALUE(LEFT(AB11,2))))<=DATE(2026,8,24),0,H11*0.0118*CEILING((IF(OR(AB11="",AB11=0),TODAY(),DATE(VALUE(RIGHT(AB11,4)),VALUE(MID(AB11,4,2)),VALUE(LEFT(AB11,2))))-DATE(2026,8,22))/7,1)) | AC11: =U11+X11+AA11 | AD11: =S11-AC11 | AE11: =IF(AD11="","",IF(AD11<=5,"SETTLED","OUTSTANDING")) | AF11: DR2640100032 | AG11: 1800003304 | AH11: 27.08.2026 | AL11: =IF($A$2="",1,IF($A$2="(blank)",--(A11=""),IF($A$2="(nonblank)",--(A11<>""),--ISNUMBER(SEARCH($A$2,A11))))) | AM11: =IF($B$2="",1,IF($B$2="(blank)",--(B11=""),IF($B$2="(nonblank)",--(B11<>""),--ISNUMBER(SEARCH($B$2,B11))))) | AN11: =IF($C$2="",1,IF($C$2="(blank)",--(C11=""),IF($C$2="(nonblank)",--(C11<>""),--ISNUMBER(SEARCH($C$2,C11))))) | AO11: =IF($D$2="",1,IF($D$2="(blank)",--(D11=""),IF($D$2="(nonblank)",--(D11<>""),--ISNUMBER(SEARCH($D$2,D11))))) | AP11: =IF($E$2="",1,IF($E$2="(blank)",--(E11=""),IF($E$2="(nonblank)",--(E11<>""),--ISNUMBER(SEARCH($E$2,E11))))) | AQ11: =IF($F$2="",1,IF($F$2="(blank)",--(F11=""),IF($F$2="(nonblank)",--(F11<>""),--ISNUMBER(SEARCH($F$2,F11))))) | AR11: =IF($G$2="",1,IF($G$2="(blank)",--(G11=""),IF($G$2="(nonblank)",--(G11<>""),--ISNUMBER(SEARCH($G$2,G11))))) | AS11: =IF($H$2="",1,IF($H$2="(blank)",--(H11=""),IF($H$2="(nonblank)",--(H11<>""),--ISNUMBER(SEARCH($H$2,H11))))) | AT11: =IF($I$2="",1,IF($I$2="(blank)",--(I11=""),IF($I$2="(nonblank)",--(I11<>""),--ISNUMBER(SEARCH($I$2,I11))))) | AU11: =IF($J$2="",1,IF($J$2="(blank)",--(J11=""),IF($J$2="(nonblank)",--(J11<>""),--ISNUMBER(SEARCH($J$2,J11))))) | AV11: =IF($K$2="",1,IF($K$2="(blank)",--(K11=""),IF($K$2="(nonblank)",--(K11<>""),--ISNUMBER(SEARCH($K$2,K11))))) | AW11: =IF($L$2="",1,IF($L$2="(blank)",--(L11=""),IF($L$2="(nonblank)",--(L11<>""),--ISNUMBER(SEARCH($L$2,L11))))) | AX11: =IF($M$2="",1,IF($M$2="(blank)",--(M11=""),IF($M$2="(nonblank)",--(M11<>""),--ISNUMBER(SEARCH($M$2,M11))))) | AY11: =IF($N$2="",1,IF($N$2="(blank)",--(N11=""),IF($N$2="(nonblank)",--(N11<>""),--ISNUMBER(SEARCH($N$2,N11))))) | AZ11: =IF($O$2="",1,IF($O$2="(blank)",--(O11=""),IF($O$2="(nonblank)",--(O11<>""),--ISNUMBER(SEARCH($O$2,O11))))) | BA11: =IF($P$2="",1,IF($P$2="(blank)",--(P11=""),IF($P$2="(nonblank)",--(P11<>""),--ISNUMBER(SEARCH($P$2,P11))))) | BB11: =IF($Q$2="",1,IF($Q$2="(blank)",--(Q11=""),IF($Q$2="(nonblank)",--(Q11<>""),--ISNUMBER(SEARCH($Q$2,Q11))))) | BC11: =IF($R$2="",1,IF($R$2="(blank)",--(R11=""),IF($R$2="(nonblank)",--(R11<>""),--ISNUMBER(SEARCH($R$2,R11))))) | BD11: =IF($S$2="",1,IF($S$2="(blank)",--(S11=""),IF($S$2="(nonblank)",--(S11<>""),--ISNUMBER(SEARCH($S$2,S11))))) | BE11: =IF($T$2="",1,IF($T$2="(blank)",--(T11=""),IF($T$2="(nonblank)",--(T11<>""),--ISNUMBER(SEARCH($T$2,T11))))) | BF11: =IF($U$2="",1,IF($U$2="(blank)",--(U11=""),IF($U$2="(nonblank)",--(U11<>""),--ISNUMBER(SEARCH($U$2,U11))))) | BG11: =IF($V$2="",1,IF($V$2="(blank)",--(V11=""),IF($V$2="(nonblank)",--(V11<>""),--ISNUMBER(SEARCH($V$2,V11))))) | BH11: =IF($W$2="",1,IF($W$2="(blank)",--(W11=""),IF($W$2="(nonblank)",--(W11<>""),--ISNUMBER(SEARCH($W$2,W11))))) | BI11: =IF($X$2="",1,IF($X$2="(blank)",--(X11=""),IF($X$2="(nonblank)",--(X11<>""),--ISNUMBER(SEARCH($X$2,X11))))) | BJ11: =IF($Y$2="",1,IF($Y$2="(blank)",--(Y11=""),IF($Y$2="(nonblank)",--(Y11<>""),--ISNUMBER(SEARCH($Y$2,Y11))))) | BK11: =IF($Z$2="",1,IF($Z$2="(blank)",--(Z11=""),IF($Z$2="(nonblank)",--(Z11<>""),--ISNUMBER(SEARCH($Z$2,Z11))))) | BL11: =IF($AA$2="",1,IF($AA$2="(blank)",--(AA11=""),IF($AA$2="(nonblank)",--(AA11<>""),--ISNUMBER(SEARCH($AA$2,AA11))))) | BM11: =IF($AB$2="",1,IF($AB$2="(blank)",--(AB11=""),IF($AB$2="(nonblank)",--(AB11<>""),--ISNUMBER(SEARCH($AB$2,AB11))))) | BN11: =IF($AC$2="",1,IF($AC$2="(blank)",--(AC11=""),IF($AC$2="(nonblank)",--(AC11<>""),--ISNUMBER(SEARCH($AC$2,AC11))))) | BO11: =IF($AD$2="",1,IF($AD$2="(blank)",--(AD11=""),IF($AD$2="(nonblank)",--(AD11<>""),--ISNUMBER(SEARCH($AD$2,AD11))))) | BP11: =IF($AE$2="",1,IF($AE$2="(blank)",--(AE11=""),IF($AE$2="(nonblank)",--(AE11<>""),--ISNUMBER(SEARCH($AE$2,AE11))))) | BQ11: =IF($AF$2="",1,IF($AF$2="(blank)",--(AF11=""),IF($AF$2="(nonblank)",--(AF11<>""),--ISNUMBER(SEARCH($AF$2,AF11))))) | BR11: =IF($AG$2="",1,IF($AG$2="(blank)",--(AG11=""),IF($AG$2="(nonblank)",--(AG11<>""),--ISNUMBER(SEARCH($AG$2,AG11))))) | BS11: =IF($AH$2="",1,IF($AH$2="(blank)",--(AH11=""),IF($AH$2="(nonblank)",--(AH11<>""),--ISNUMBER(SEARCH($AH$2,AH11))))) | BT11: =IF(COUNTIF($AL11:$BS11,0)>0,0,1)
A12: 1 | B12: Scrap of 220KV CT | C12: 70006 | D12: 21977 | E12: NO | F12: 2005 | G12: NATIONAL ENTERPRISES | H12: 70006 | I12: =ROUND(H12*18%,0) | J12: =+H12+I12 | K12: =ROUND((H12+I12)*2%,0) | L12: =H12*0.1% | M12: =H12*2.25%*118% | N12: =H12*2.25%*2% | O12: =M12-N12 | P12: =ROUND(O12+L12,0) | Q12: 0 | R12: =ROUND(H12*Q12,0) | S12: =ROUND(H12*117.65%-R12,0) | T12: =ROUND(H12*25%,0) | U12: =+T12 | V12: 13.08.2026 | W12: =ROUND(H12*92.65%-R12,0) | X12: 64859 | Y12: 24.08.2026 | Z12: =IF(IF(OR(AB12="",AB12=0),TODAY(),DATE(VALUE(RIGHT(AB12,4)),VALUE(MID(AB12,4,2)),VALUE(LEFT(AB12,2))))<=DATE(2026,8,24),0,H12*0.0118*CEILING((IF(OR(AB12="",AB12=0),TODAY(),DATE(VALUE(RIGHT(AB12,4)),VALUE(MID(AB12,4,2)),VALUE(LEFT(AB12,2))))-DATE(2026,8,22))/7,1)) | AC12: =U12+X12+AA12 | AD12: =S12-AC12 | AE12: =IF(AD12="","",IF(AD12<=5,"SETTLED","OUTSTANDING")) | AF12: DR2640100033 | AG12: 1800003305 | AH12: 27.08.2026 | AL12: =IF($A$2="",1,IF($A$2="(blank)",--(A12=""),IF($A$2="(nonblank)",--(A12<>""),--ISNUMBER(SEARCH($A$2,A12))))) | AM12: =IF($B$2="",1,IF($B$2="(blank)",--(B12=""),IF($B$2="(nonblank)",--(B12<>""),--ISNUMBER(SEARCH($B$2,B12))))) | AN12: =IF($C$2="",1,IF($C$2="(blank)",--(C12=""),IF($C$2="(nonblank)",--(C12<>""),--ISNUMBER(SEARCH($C$2,C12))))) | AO12: =IF($D$2="",1,IF($D$2="(blank)",--(D12=""),IF($D$2="(nonblank)",--(D12<>""),--ISNUMBER(SEARCH($D$2,D12))))) | AP12: =IF($E$2="",1,IF($E$2="(blank)",--(E12=""),IF($E$2="(nonblank)",--(E12<>""),--ISNUMBER(SEARCH($E$2,E12))))) | AQ12: =IF($F$2="",1,IF($F$2="(blank)",--(F12=""),IF($F$2="(nonblank)",--(F12<>""),--ISNUMBER(SEARCH($F$2,F12))))) | AR12: =IF($G$2="",1,IF($G$2="(blank)",--(G12=""),IF($G$2="(nonblank)",--(G12<>""),--ISNUMBER(SEARCH($G$2,G12))))) | AS12: =IF($H$2="",1,IF($H$2="(blank)",--(H12=""),IF($H$2="(nonblank)",--(H12<>""),--ISNUMBER(SEARCH($H$2,H12))))) | AT12: =IF($I$2="",1,IF($I$2="(blank)",--(I12=""),IF($I$2="(nonblank)",--(I12<>""),--ISNUMBER(SEARCH($I$2,I12))))) | AU12: =IF($J$2="",1,IF($J$2="(blank)",--(J12=""),IF($J$2="(nonblank)",--(J12<>""),--ISNUMBER(SEARCH($J$2,J12))))) | AV12: =IF($K$2="",1,IF($K$2="(blank)",--(K12=""),IF($K$2="(nonblank)",--(K12<>""),--ISNUMBER(SEARCH($K$2,K12))))) | AW12: =IF($L$2="",1,IF($L$2="(blank)",--(L12=""),IF($L$2="(nonblank)",--(L12<>""),--ISNUMBER(SEARCH($L$2,L12))))) | AX12: =IF($M$2="",1,IF($M$2="(blank)",--(M12=""),IF($M$2="(nonblank)",--(M12<>""),--ISNUMBER(SEARCH($M$2,M12))))) | AY12: =IF($N$2="",1,IF($N$2="(blank)",--(N12=""),IF($N$2="(nonblank)",--(N12<>""),--ISNUMBER(SEARCH($N$2,N12))))) | AZ12: =IF($O$2="",1,IF($O$2="(blank)",--(O12=""),IF($O$2="(nonblank)",--(O12<>""),--ISNUMBER(SEARCH($O$2,O12))))) | BA12: =IF($P$2="",1,IF($P$2="(blank)",--(P12=""),IF($P$2="(nonblank)",--(P12<>""),--ISNUMBER(SEARCH($P$2,P12))))) | BB12: =IF($Q$2="",1,IF($Q$2="(blank)",--(Q12=""),IF($Q$2="(nonblank)",--(Q12<>""),--ISNUMBER(SEARCH($Q$2,Q12))))) | BC12: =IF($R$2="",1,IF($R$2="(blank)",--(R12=""),IF($R$2="(nonblank)",--(R12<>""),--ISNUMBER(SEARCH($R$2,R12))))) | BD12: =IF($S$2="",1,IF($S$2="(blank)",--(S12=""),IF($S$2="(nonblank)",--(S12<>""),--ISNUMBER(SEARCH($S$2,S12))))) | BE12: =IF($T$2="",1,IF($T$2="(blank)",--(T12=""),IF($T$2="(nonblank)",--(T12<>""),--ISNUMBER(SEARCH($T$2,T12))))) | BF12: =IF($U$2="",1,IF($U$2="(blank)",--(U12=""),IF($U$2="(nonblank)",--(U12<>""),--ISNUMBER(SEARCH($U$2,U12))))) | BG12: =IF($V$2="",1,IF($V$2="(blank)",--(V12=""),IF($V$2="(nonblank)",--(V12<>""),--ISNUMBER(SEARCH($V$2,V12))))) | BH12: =IF($W$2="",1,IF($W$2="(blank)",--(W12=""),IF($W$2="(nonblank)",--(W12<>""),--ISNUMBER(SEARCH($W$2,W12))))) | BI12: =IF($X$2="",1,IF($X$2="(blank)",--(X12=""),IF($X$2="(nonblank)",--(X12<>""),--ISNUMBER(SEARCH($X$2,X12))))) | BJ12: =IF($Y$2="",1,IF($Y$2="(blank)",--(Y12=""),IF($Y$2="(nonblank)",--(Y12<>""),--ISNUMBER(SEARCH($Y$2,Y12))))) | BK12: =IF($Z$2="",1,IF($Z$2="(blank)",--(Z12=""),IF($Z$2="(nonblank)",--(Z12<>""),--ISNUMBER(SEARCH($Z$2,Z12))))) | BL12: =IF($AA$2="",1,IF($AA$2="(blank)",--(AA12=""),IF($AA$2="(nonblank)",--(AA12<>""),--ISNUMBER(SEARCH($AA$2,AA12))))) | BM12: =IF($AB$2="",1,IF($AB$2="(blank)",--(AB12=""),IF($AB$2="(nonblank)",--(AB12<>""),--ISNUMBER(SEARCH($AB$2,AB12))))) | BN12: =IF($AC$2="",1,IF($AC$2="(blank)",--(AC12=""),IF($AC$2="(nonblank)",--(AC12<>""),--ISNUMBER(SEARCH($AC$2,AC12))))) | BO12: =IF($AD$2="",1,IF($AD$2="(blank)",--(AD12=""),IF($AD$2="(nonblank)",--(AD12<>""),--ISNUMBER(SEARCH($AD$2,AD12))))) | BP12: =IF($AE$2="",1,IF($AE$2="(blank)",--(AE12=""),IF($AE$2="(nonblank)",--(AE12<>""),--ISNUMBER(SEARCH($AE$2,AE12))))) | BQ12: =IF($AF$2="",1,IF($AF$2="(blank)",--(AF12=""),IF($AF$2="(nonblank)",--(AF12<>""),--ISNUMBER(SEARCH($AF$2,AF12))))) | BR12: =IF($AG$2="",1,IF($AG$2="(blank)",--(AG12=""),IF($AG$2="(nonblank)",--(AG12<>""),--ISNUMBER(SEARCH($AG$2,AG12))))) | BS12: =IF($AH$2="",1,IF($AH$2="(blank)",--(AH12=""),IF($AH$2="(nonblank)",--(AH12<>""),--ISNUMBER(SEARCH($AH$2,AH12))))) | BT12: =IF(COUNTIF($AL12:$BS12,0)>0,0,1)
A13: 25 | B13: Scrap of empty oil drums | C13: 700 | D13: 21977 | E13: NO | F13: 2006 | G13: STERLING ENTERPRISES | H13: 17500 | I13: =ROUND(H13*18%,0) | J13: =+H13+I13 | K13: =ROUND((H13+I13)*2%,0) | L13: =H13*0.1% | M13: =H13*2.25%*118% | N13: =H13*2.25%*2% | O13: =M13-N13 | P13: =ROUND(O13+L13,0) | Q13: 0 | R13: =ROUND(H13*Q13,0) | S13: =ROUND(H13*117.65%-R13,0) | T13: =ROUND(H13*25%,0) | U13: 4375 | V13: 11.08.2026 | W13: =ROUND(H13*92.65%-R13,0) | X13: 16214 | Y13: 11.08.2026 | Z13: =IF(IF(OR(AB13="",AB13=0),TODAY(),DATE(VALUE(RIGHT(AB13,4)),VALUE(MID(AB13,4,2)),VALUE(LEFT(AB13,2))))<=DATE(2026,8,24),0,H13*0.0118*CEILING((IF(OR(AB13="",AB13=0),TODAY(),DATE(VALUE(RIGHT(AB13,4)),VALUE(MID(AB13,4,2)),VALUE(LEFT(AB13,2))))-DATE(2026,8,22))/7,1)) | AC13: =U13+X13+AA13 | AD13: =S13-AC13 | AE13: =IF(AD13="","",IF(AD13<=5,"SETTLED","OUTSTANDING")) | AF13: DR2640100018 | AG13: 1800003156 | AH13: 14.08.2026 | AL13: =IF($A$2="",1,IF($A$2="(blank)",--(A13=""),IF($A$2="(nonblank)",--(A13<>""),--ISNUMBER(SEARCH($A$2,A13))))) | AM13: =IF($B$2="",1,IF($B$2="(blank)",--(B13=""),IF($B$2="(nonblank)",--(B13<>""),--ISNUMBER(SEARCH($B$2,B13))))) | AN13: =IF($C$2="",1,IF($C$2="(blank)",--(C13=""),IF($C$2="(nonblank)",--(C13<>""),--ISNUMBER(SEARCH($C$2,C13))))) | AO13: =IF($D$2="",1,IF($D$2="(blank)",--(D13=""),IF($D$2="(nonblank)",--(D13<>""),--ISNUMBER(SEARCH($D$2,D13))))) | AP13: =IF($E$2="",1,IF($E$2="(blank)",--(E13=""),IF($E$2="(nonblank)",--(E13<>""),--ISNUMBER(SEARCH($E$2,E13))))) | AQ13: =IF($F$2="",1,IF($F$2="(blank)",--(F13=""),IF($F$2="(nonblank)",--(F13<>""),--ISNUMBER(SEARCH($F$2,F13))))) | AR13: =IF($G$2="",1,IF($G$2="(blank)",--(G13=""),IF($G$2="(nonblank)",--(G13<>""),--ISNUMBER(SEARCH($G$2,G13))))) | AS13: =IF($H$2="",1,IF($H$2="(blank)",--(H13=""),IF($H$2="(nonblank)",--(H13<>""),--ISNUMBER(SEARCH($H$2,H13))))) | AT13: =IF($I$2="",1,IF($I$2="(blank)",--(I13=""),IF($I$2="(nonblank)",--(I13<>""),--ISNUMBER(SEARCH($I$2,I13))))) | AU13: =IF($J$2="",1,IF($J$2="(blank)",--(J13=""),IF($J$2="(nonblank)",--(J13<>""),--ISNUMBER(SEARCH($J$2,J13))))) | AV13: =IF($K$2="",1,IF($K$2="(blank)",--(K13=""),IF($K$2="(nonblank)",--(K13<>""),--ISNUMBER(SEARCH($K$2,K13))))) | AW13: =IF($L$2="",1,IF($L$2="(blank)",--(L13=""),IF($L$2="(nonblank)",--(L13<>""),--ISNUMBER(SEARCH($L$2,L13))))) | AX13: =IF($M$2="",1,IF($M$2="(blank)",--(M13=""),IF($M$2="(nonblank)",--(M13<>""),--ISNUMBER(SEARCH($M$2,M13))))) | AY13: =IF($N$2="",1,IF($N$2="(blank)",--(N13=""),IF($N$2="(nonblank)",--(N13<>""),--ISNUMBER(SEARCH($N$2,N13))))) | AZ13: =IF($O$2="",1,IF($O$2="(blank)",--(O13=""),IF($O$2="(nonblank)",--(O13<>""),--ISNUMBER(SEARCH($O$2,O13))))) | BA13: =IF($P$2="",1,IF($P$2="(blank)",--(P13=""),IF($P$2="(nonblank)",--(P13<>""),--ISNUMBER(SEARCH($P$2,P13))))) | BB13: =IF($Q$2="",1,IF($Q$2="(blank)",--(Q13=""),IF($Q$2="(nonblank)",--(Q13<>""),--ISNUMBER(SEARCH($Q$2,Q13))))) | BC13: =IF($R$2="",1,IF($R$2="(blank)",--(R13=""),IF($R$2="(nonblank)",--(R13<>""),--ISNUMBER(SEARCH($R$2,R13))))) | BD13: =IF($S$2="",1,IF($S$2="(blank)",--(S13=""),IF($S$2="(nonblank)",--(S13<>""),--ISNUMBER(SEARCH($S$2,S13))))) | BE13: =IF($T$2="",1,IF($T$2="(blank)",--(T13=""),IF($T$2="(nonblank)",--(T13<>""),--ISNUMBER(SEARCH($T$2,T13))))) | BF13: =IF($U$2="",1,IF($U$2="(blank)",--(U13=""),IF($U$2="(nonblank)",--(U13<>""),--ISNUMBER(SEARCH($U$2,U13))))) | BG13: =IF($V$2="",1,IF($V$2="(blank)",--(V13=""),IF($V$2="(nonblank)",--(V13<>""),--ISNUMBER(SEARCH($V$2,V13))))) | BH13: =IF($W$2="",1,IF($W$2="(blank)",--(W13=""),IF($W$2="(nonblank)",--(W13<>""),--ISNUMBER(SEARCH($W$2,W13))))) | BI13: =IF($X$2="",1,IF($X$2="(blank)",--(X13=""),IF($X$2="(nonblank)",--(X13<>""),--ISNUMBER(SEARCH($X$2,X13))))) | BJ13: =IF($Y$2="",1,IF($Y$2="(blank)",--(Y13=""),IF($Y$2="(nonblank)",--(Y13<>""),--ISNUMBER(SEARCH($Y$2,Y13))))) | BK13: =IF($Z$2="",1,IF($Z$2="(blank)",--(Z13=""),IF($Z$2="(nonblank)",--(Z13<>""),--ISNUMBER(SEARCH($Z$2,Z13))))) | BL13: =IF($AA$2="",1,IF($AA$2="(blank)",--(AA13=""),IF($AA$2="(nonblank)",--(AA13<>""),--ISNUMBER(SEARCH($AA$2,AA13))))) | BM13: =IF($AB$2="",1,IF($AB$2="(blank)",--(AB13=""),IF($AB$2="(nonblank)",--(AB13<>""),--ISNUMBER(SEARCH($AB$2,AB13))))) | BN13: =IF($AC$2="",1,IF($AC$2="(blank)",--(AC13=""),IF($AC$2="(nonblank)",--(AC13<>""),--ISNUMBER(SEARCH($AC$2,AC13))))) | BO13: =IF($AD$2="",1,IF($AD$2="(blank)",--(AD13=""),IF($AD$2="(nonblank)",--(AD13<>""),--ISNUMBER(SEARCH($AD$2,AD13))))) | BP13: =IF($AE$2="",1,IF($AE$2="(blank)",--(AE13=""),IF($AE$2="(nonblank)",--(AE13<>""),--ISNUMBER(SEARCH($AE$2,AE13))))) | BQ13: =IF($AF$2="",1,IF($AF$2="(blank)",--(AF13=""),IF($AF$2="(nonblank)",--(AF13<>""),--ISNUMBER(SEARCH($AF$2,AF13))))) | BR13: =IF($AG$2="",1,IF($AG$2="(blank)",--(AG13=""),IF($AG$2="(nonblank)",--(AG13<>""),--ISNUMBER(SEARCH($AG$2,AG13))))) | BS13: =IF($AH$2="",1,IF($AH$2="(blank)",--(AH13=""),IF($AH$2="(nonblank)",--(AH13<>""),--ISNUMBER(SEARCH($AH$2,AH13))))) | BT13: =IF(COUNTIF($AL13:$BS13,0)>0,0,1)
A14: 1 | B14: SCRAP POWER TRANSFORMER | C14: 3857116 | D14: 21977 | E14: NO | F14: 2007 | G14: SHAR JAHAN TRADERS | H14: 3857116 | I14: =ROUND(H14*18%,0) | J14: =+H14+I14 | K14: =ROUND((H14+I14)*2%,0) | L14: =H14*0.1% | M14: =H14*2.25%*118% | N14: =H14*2.25%*2% | O14: =M14-N14 | P14: =ROUND(O14+L14,0) | Q14: 0 | R14: =ROUND(H14*Q14,0) | S14: =ROUND(H14*117.65%-R14,0) | T14: =ROUND(H14*25%,0) | U14: =+T14 | V14: 13.08.2026 | W14: =ROUND(H14*92.65%-R14,0) | X14: 3573618.9 | Y14: 13.08.2026 | Z14: =IF(IF(OR(AB14="",AB14=0),TODAY(),DATE(VALUE(RIGHT(AB14,4)),VALUE(MID(AB14,4,2)),VALUE(LEFT(AB14,2))))<=DATE(2026,8,24),0,H14*0.0118*CEILING((IF(OR(AB14="",AB14=0),TODAY(),DATE(VALUE(RIGHT(AB14,4)),VALUE(MID(AB14,4,2)),VALUE(LEFT(AB14,2))))-DATE(2026,8,22))/7,1)) | AC14: =U14+X14+AA14 | AD14: =S14-AC14 | AE14: =IF(AD14="","",IF(AD14<=5,"SETTLED","OUTSTANDING")) | AF14: DR2640100024 | AG14: 1800003196 | AH14: 17.08.2026 | AL14: =IF($A$2="",1,IF($A$2="(blank)",--(A14=""),IF($A$2="(nonblank)",--(A14<>""),--ISNUMBER(SEARCH($A$2,A14))))) | AM14: =IF($B$2="",1,IF($B$2="(blank)",--(B14=""),IF($B$2="(nonblank)",--(B14<>""),--ISNUMBER(SEARCH($B$2,B14))))) | AN14: =IF($C$2="",1,IF($C$2="(blank)",--(C14=""),IF($C$2="(nonblank)",--(C14<>""),--ISNUMBER(SEARCH($C$2,C14))))) | AO14: =IF($D$2="",1,IF($D$2="(blank)",--(D14=""),IF($D$2="(nonblank)",--(D14<>""),--ISNUMBER(SEARCH($D$2,D14))))) | AP14: =IF($E$2="",1,IF($E$2="(blank)",--(E14=""),IF($E$2="(nonblank)",--(E14<>""),--ISNUMBER(SEARCH($E$2,E14))))) | AQ14: =IF($F$2="",1,IF($F$2="(blank)",--(F14=""),IF($F$2="(nonblank)",--(F14<>""),--ISNUMBER(SEARCH($F$2,F14))))) | AR14: =IF($G$2="",1,IF($G$2="(blank)",--(G14=""),IF($G$2="(nonblank)",--(G14<>""),--ISNUMBER(SEARCH($G$2,G14))))) | AS14: =IF($H$2="",1,IF($H$2="(blank)",--(H14=""),IF($H$2="(nonblank)",--(H14<>""),--ISNUMBER(SEARCH($H$2,H14))))) | AT14: =IF($I$2="",1,IF($I$2="(blank)",--(I14=""),IF($I$2="(nonblank)",--(I14<>""),--ISNUMBER(SEARCH($I$2,I14))))) | AU14: =IF($J$2="",1,IF($J$2="(blank)",--(J14=""),IF($J$2="(nonblank)",--(J14<>""),--ISNUMBER(SEARCH($J$2,J14))))) | AV14: =IF($K$2="",1,IF($K$2="(blank)",--(K14=""),IF($K$2="(nonblank)",--(K14<>""),--ISNUMBER(SEARCH($K$2,K14))))) | AW14: =IF($L$2="",1,IF($L$2="(blank)",--(L14=""),IF($L$2="(nonblank)",--(L14<>""),--ISNUMBER(SEARCH($L$2,L14))))) | AX14: =IF($M$2="",1,IF($M$2="(blank)",--(M14=""),IF($M$2="(nonblank)",--(M14<>""),--ISNUMBER(SEARCH($M$2,M14))))) | AY14: =IF($N$2="",1,IF($N$2="(blank)",--(N14=""),IF($N$2="(nonblank)",--(N14<>""),--ISNUMBER(SEARCH($N$2,N14))))) | AZ14: =IF($O$2="",1,IF($O$2="(blank)",--(O14=""),IF($O$2="(nonblank)",--(O14<>""),--ISNUMBER(SEARCH($O$2,O14))))) | BA14: =IF($P$2="",1,IF($P$2="(blank)",--(P14=""),IF($P$2="(nonblank)",--(P14<>""),--ISNUMBER(SEARCH($P$2,P14))))) | BB14: =IF($Q$2="",1,IF($Q$2="(blank)",--(Q14=""),IF($Q$2="(nonblank)",--(Q14<>""),--ISNUMBER(SEARCH($Q$2,Q14))))) | BC14: =IF($R$2="",1,IF($R$2="(blank)",--(R14=""),IF($R$2="(nonblank)",--(R14<>""),--ISNUMBER(SEARCH($R$2,R14))))) | BD14: =IF($S$2="",1,IF($S$2="(blank)",--(S14=""),IF($S$2="(nonblank)",--(S14<>""),--ISNUMBER(SEARCH($S$2,S14))))) | BE14: =IF($T$2="",1,IF($T$2="(blank)",--(T14=""),IF($T$2="(nonblank)",--(T14<>""),--ISNUMBER(SEARCH($T$2,T14))))) | BF14: =IF($U$2="",1,IF($U$2="(blank)",--(U14=""),IF($U$2="(nonblank)",--(U14<>""),--ISNUMBER(SEARCH($U$2,U14))))) | BG14: =IF($V$2="",1,IF($V$2="(blank)",--(V14=""),IF($V$2="(nonblank)",--(V14<>""),--ISNUMBER(SEARCH($V$2,V14))))) | BH14: =IF($W$2="",1,IF($W$2="(blank)",--(W14=""),IF($W$2="(nonblank)",--(W14<>""),--ISNUMBER(SEARCH($W$2,W14))))) | BI14: =IF($X$2="",1,IF($X$2="(blank)",--(X14=""),IF($X$2="(nonblank)",--(X14<>""),--ISNUMBER(SEARCH($X$2,X14))))) | BJ14: =IF($Y$2="",1,IF($Y$2="(blank)",--(Y14=""),IF($Y$2="(nonblank)",--(Y14<>""),--ISNUMBER(SEARCH($Y$2,Y14))))) | BK14: =IF($Z$2="",1,IF($Z$2="(blank)",--(Z14=""),IF($Z$2="(nonblank)",--(Z14<>""),--ISNUMBER(SEARCH($Z$2,Z14))))) | BL14: =IF($AA$2="",1,IF($AA$2="(blank)",--(AA14=""),IF($AA$2="(nonblank)",--(AA14<>""),--ISNUMBER(SEARCH($AA$2,AA14))))) | BM14: =IF($AB$2="",1,IF($AB$2="(blank)",--(AB14=""),IF($AB$2="(nonblank)",--(AB14<>""),--ISNUMBER(SEARCH($AB$2,AB14))))) | BN14: =IF($AC$2="",1,IF($AC$2="(blank)",--(AC14=""),IF($AC$2="(nonblank)",--(AC14<>""),--ISNUMBER(SEARCH($AC$2,AC14))))) | BO14: =IF($AD$2="",1,IF($AD$2="(blank)",--(AD14=""),IF($AD$2="(nonblank)",--(AD14<>""),--ISNUMBER(SEARCH($AD$2,AD14))))) | BP14: =IF($AE$2="",1,IF($AE$2="(blank)",--(AE14=""),IF($AE$2="(nonblank)",--(AE14<>""),--ISNUMBER(SEARCH($AE$2,AE14))))) | BQ14: =IF($AF$2="",1,IF($AF$2="(blank)",--(AF14=""),IF($AF$2="(nonblank)",--(AF14<>""),--ISNUMBER(SEARCH($AF$2,AF14))))) | BR14: =IF($AG$2="",1,IF($AG$2="(blank)",--(AG14=""),IF($AG$2="(nonblank)",--(AG14<>""),--ISNUMBER(SEARCH($AG$2,AG14))))) | BS14: =IF($AH$2="",1,IF($AH$2="(blank)",--(AH14=""),IF($AH$2="(nonblank)",--(AH14<>""),--ISNUMBER(SEARCH($AH$2,AH14))))) | BT14: =IF(COUNTIF($AL14:$BS14,0)>0,0,1)
